{
 "cells": [
  {
   "cell_type": "code",
   "execution_count": 9,
   "metadata": {},
   "outputs": [],
   "source": [
    "import os\n",
    "import json\n",
    "from pathlib import Path\n",
    "import logging\n",
    "import time\n",
    "import random\n",
    "from queue import Queue\n",
    "import sys\n",
    "\n",
    "from PIL import Image\n",
    "from dotenv import load_dotenv\n",
    "\n",
    "sys.path.append(os.path.abspath('..'))\n",
    "\n",
    "from gemini_api import GeminiAPIHandler\n",
    "\n",
    "api_requests_file = \"../api_requests/api_requests_derm12345.json\"\n",
    "output_dir = \"../api_results/derm12345\"\n",
    "os.makedirs(os.path.dirname(output_dir), exist_ok=True)\n",
    "\n",
    "log_filename = os.path.join(output_dir, f\"api_resultscont.log\")\n",
    "os.makedirs(os.path.dirname(log_filename), exist_ok=True)\n",
    "logging.basicConfig(\n",
    "    level=logging.INFO, \n",
    "    format='%(asctime)s - %(name)s - %(levelname)s - %(message)s', \n",
    "    filename=log_filename\n",
    ")\n",
    "logger = logging.getLogger(__name__)"
   ]
  },
  {
   "cell_type": "code",
   "execution_count": 10,
   "metadata": {},
   "outputs": [
    {
     "name": "stdout",
     "output_type": "stream",
     "text": [
      "The history saving thread hit an unexpected error (OperationalError('unable to open database file')).History will not be written to the database.\n"
     ]
    }
   ],
   "source": [
    "load_dotenv(dotenv_path=\"../../.env\")\n",
    "api_key = os.getenv(\"GEMINI_API_KEY\")\n",
    "\n",
    "model_name = \"gemini-2.0-flash-exp\"\n",
    "#model_name = \"gemini-2.0-flash-thinking-exp\"\n",
    "\n",
    "api_handler = GeminiAPIHandler(api_key=api_key, model_name=model_name)\n",
    "\n",
    "with open(api_requests_file, \"r\") as file:\n",
    "    api_requests = json.load(file)"
   ]
  },
  {
   "cell_type": "code",
   "execution_count": 11,
   "metadata": {},
   "outputs": [],
   "source": [
    "def call_gemini_api(request: dict) -> dict:\n",
    "    \"\"\"\n",
    "    Call the Gemini API for a given request and dataset image path.\n",
    "    \"\"\"\n",
    "    image_id = request.get(\"image_id\")\n",
    "    image_path = request.get(\"image_path\")\n",
    "            \n",
    "    # Get 2 prompts\n",
    "    q1_general = request.get(\"q1_general\")['prompt']\n",
    "    q2_dataset_specific = request.get(\"q2_dataset_specific\")['prompt']\n",
    "    \n",
    "    # Load the image\n",
    "    with Image.open(image_path) as pil_image:\n",
    "        # Generate response for general prompt\n",
    "        q1_general_response = api_handler.generate_from_pil_image(pil_image, q1_general)\n",
    "        # Generate response for dataset-specific prompt\n",
    "        q2_dataset_response = api_handler.generate_from_pil_image(pil_image, q2_dataset_specific)\n",
    "        \n",
    "    # Save the responses\n",
    "    result = {\n",
    "        \"image_id\": image_id,\n",
    "        \"image_path\": image_path,\n",
    "        \n",
    "        # Save the responses\n",
    "        \"q1_general_response\": q1_general_response,\n",
    "        \"q2_dataset_response\": q2_dataset_response,\n",
    "        \n",
    "        # Save the questions\n",
    "        \"q1_general_question\": request.get(\"q1_general\")['question'],\n",
    "        \"q2_dataset_question\": request.get(\"q2_dataset_specific\")['question'],\n",
    "        \n",
    "        # Save the prompts\n",
    "        \"q1_general_prompt\": q1_general,\n",
    "        \"q2_dataset_prompt\": q2_dataset_specific\n",
    "    }\n",
    "    \n",
    "    return result"
   ]
  },
  {
   "cell_type": "code",
   "execution_count": null,
   "metadata": {},
   "outputs": [
    {
     "name": "stderr",
     "output_type": "stream",
     "text": [
      "--- Logging error ---\n",
      "Traceback (most recent call last):\n",
      "  File \"/Users/jinjiewu/anaconda3/lib/python3.11/logging/__init__.py\", line 1114, in emit\n",
      "    self.flush()\n",
      "  File \"/Users/jinjiewu/anaconda3/lib/python3.11/logging/__init__.py\", line 1094, in flush\n",
      "    self.stream.flush()\n",
      "OSError: [Errno 28] No space left on device\n",
      "Call stack:\n",
      "  File \"<frozen runpy>\", line 198, in _run_module_as_main\n",
      "  File \"<frozen runpy>\", line 88, in _run_code\n",
      "  File \"/Users/jinjiewu/anaconda3/lib/python3.11/site-packages/ipykernel_launcher.py\", line 17, in <module>\n",
      "    app.launch_new_instance()\n",
      "  File \"/Users/jinjiewu/anaconda3/lib/python3.11/site-packages/traitlets/config/application.py\", line 992, in launch_instance\n",
      "    app.start()\n",
      "  File \"/Users/jinjiewu/anaconda3/lib/python3.11/site-packages/ipykernel/kernelapp.py\", line 736, in start\n",
      "    self.io_loop.start()\n",
      "  File \"/Users/jinjiewu/anaconda3/lib/python3.11/site-packages/tornado/platform/asyncio.py\", line 195, in start\n",
      "    self.asyncio_loop.run_forever()\n",
      "  File \"/Users/jinjiewu/anaconda3/lib/python3.11/asyncio/base_events.py\", line 607, in run_forever\n",
      "    self._run_once()\n",
      "  File \"/Users/jinjiewu/anaconda3/lib/python3.11/asyncio/base_events.py\", line 1922, in _run_once\n",
      "    handle._run()\n",
      "  File \"/Users/jinjiewu/anaconda3/lib/python3.11/asyncio/events.py\", line 80, in _run\n",
      "    self._context.run(self._callback, *self._args)\n",
      "  File \"/Users/jinjiewu/anaconda3/lib/python3.11/site-packages/ipykernel/kernelbase.py\", line 516, in dispatch_queue\n",
      "    await self.process_one()\n",
      "  File \"/Users/jinjiewu/anaconda3/lib/python3.11/site-packages/ipykernel/kernelbase.py\", line 505, in process_one\n",
      "    await dispatch(*args)\n",
      "  File \"/Users/jinjiewu/anaconda3/lib/python3.11/site-packages/ipykernel/kernelbase.py\", line 412, in dispatch_shell\n",
      "    await result\n",
      "  File \"/Users/jinjiewu/anaconda3/lib/python3.11/site-packages/ipykernel/kernelbase.py\", line 740, in execute_request\n",
      "    reply_content = await reply_content\n",
      "  File \"/Users/jinjiewu/anaconda3/lib/python3.11/site-packages/ipykernel/ipkernel.py\", line 422, in do_execute\n",
      "    res = shell.run_cell(\n",
      "  File \"/Users/jinjiewu/anaconda3/lib/python3.11/site-packages/ipykernel/zmqshell.py\", line 546, in run_cell\n",
      "    return super().run_cell(*args, **kwargs)\n",
      "  File \"/Users/jinjiewu/anaconda3/lib/python3.11/site-packages/IPython/core/interactiveshell.py\", line 3024, in run_cell\n",
      "    result = self._run_cell(\n",
      "  File \"/Users/jinjiewu/anaconda3/lib/python3.11/site-packages/IPython/core/interactiveshell.py\", line 3079, in _run_cell\n",
      "    result = runner(coro)\n",
      "  File \"/Users/jinjiewu/anaconda3/lib/python3.11/site-packages/IPython/core/async_helpers.py\", line 129, in _pseudo_sync_runner\n",
      "    coro.send(None)\n",
      "  File \"/Users/jinjiewu/anaconda3/lib/python3.11/site-packages/IPython/core/interactiveshell.py\", line 3284, in run_cell_async\n",
      "    has_raised = await self.run_ast_nodes(code_ast.body, cell_name,\n",
      "  File \"/Users/jinjiewu/anaconda3/lib/python3.11/site-packages/IPython/core/interactiveshell.py\", line 3466, in run_ast_nodes\n",
      "    if await self.run_code(code, result, async_=asy):\n",
      "  File \"/Users/jinjiewu/anaconda3/lib/python3.11/site-packages/IPython/core/interactiveshell.py\", line 3526, in run_code\n",
      "    exec(code_obj, self.user_global_ns, self.user_ns)\n",
      "  File \"/var/folders/vw/qhm4x34n2tzdd67qh3859yp80000gn/T/ipykernel_3458/2757584945.py\", line 15, in <module>\n",
      "    logger.info(f\"Skipping image_id {image_id} as response already exists.\")\n",
      "Message: 'Skipping image_id DERM_100202.jpg as response already exists.'\n",
      "Arguments: ()\n",
      "--- Logging error ---\n",
      "Traceback (most recent call last):\n",
      "  File \"/Users/jinjiewu/anaconda3/lib/python3.11/logging/__init__.py\", line 1114, in emit\n",
      "    self.flush()\n",
      "  File \"/Users/jinjiewu/anaconda3/lib/python3.11/logging/__init__.py\", line 1094, in flush\n",
      "    self.stream.flush()\n",
      "OSError: [Errno 28] No space left on device\n",
      "Call stack:\n",
      "  File \"<frozen runpy>\", line 198, in _run_module_as_main\n",
      "  File \"<frozen runpy>\", line 88, in _run_code\n",
      "  File \"/Users/jinjiewu/anaconda3/lib/python3.11/site-packages/ipykernel_launcher.py\", line 17, in <module>\n",
      "    app.launch_new_instance()\n",
      "  File \"/Users/jinjiewu/anaconda3/lib/python3.11/site-packages/traitlets/config/application.py\", line 992, in launch_instance\n",
      "    app.start()\n",
      "  File \"/Users/jinjiewu/anaconda3/lib/python3.11/site-packages/ipykernel/kernelapp.py\", line 736, in start\n",
      "    self.io_loop.start()\n",
      "  File \"/Users/jinjiewu/anaconda3/lib/python3.11/site-packages/tornado/platform/asyncio.py\", line 195, in start\n",
      "    self.asyncio_loop.run_forever()\n",
      "  File \"/Users/jinjiewu/anaconda3/lib/python3.11/asyncio/base_events.py\", line 607, in run_forever\n",
      "    self._run_once()\n",
      "  File \"/Users/jinjiewu/anaconda3/lib/python3.11/asyncio/base_events.py\", line 1922, in _run_once\n",
      "    handle._run()\n",
      "  File \"/Users/jinjiewu/anaconda3/lib/python3.11/asyncio/events.py\", line 80, in _run\n",
      "    self._context.run(self._callback, *self._args)\n",
      "  File \"/Users/jinjiewu/anaconda3/lib/python3.11/site-packages/ipykernel/kernelbase.py\", line 516, in dispatch_queue\n",
      "    await self.process_one()\n",
      "  File \"/Users/jinjiewu/anaconda3/lib/python3.11/site-packages/ipykernel/kernelbase.py\", line 505, in process_one\n",
      "    await dispatch(*args)\n",
      "  File \"/Users/jinjiewu/anaconda3/lib/python3.11/site-packages/ipykernel/kernelbase.py\", line 412, in dispatch_shell\n",
      "    await result\n",
      "  File \"/Users/jinjiewu/anaconda3/lib/python3.11/site-packages/ipykernel/kernelbase.py\", line 740, in execute_request\n",
      "    reply_content = await reply_content\n",
      "  File \"/Users/jinjiewu/anaconda3/lib/python3.11/site-packages/ipykernel/ipkernel.py\", line 422, in do_execute\n",
      "    res = shell.run_cell(\n",
      "  File \"/Users/jinjiewu/anaconda3/lib/python3.11/site-packages/ipykernel/zmqshell.py\", line 546, in run_cell\n",
      "    return super().run_cell(*args, **kwargs)\n",
      "  File \"/Users/jinjiewu/anaconda3/lib/python3.11/site-packages/IPython/core/interactiveshell.py\", line 3024, in run_cell\n",
      "    result = self._run_cell(\n",
      "  File \"/Users/jinjiewu/anaconda3/lib/python3.11/site-packages/IPython/core/interactiveshell.py\", line 3079, in _run_cell\n",
      "    result = runner(coro)\n",
      "  File \"/Users/jinjiewu/anaconda3/lib/python3.11/site-packages/IPython/core/async_helpers.py\", line 129, in _pseudo_sync_runner\n",
      "    coro.send(None)\n",
      "  File \"/Users/jinjiewu/anaconda3/lib/python3.11/site-packages/IPython/core/interactiveshell.py\", line 3284, in run_cell_async\n",
      "    has_raised = await self.run_ast_nodes(code_ast.body, cell_name,\n",
      "  File \"/Users/jinjiewu/anaconda3/lib/python3.11/site-packages/IPython/core/interactiveshell.py\", line 3466, in run_ast_nodes\n",
      "    if await self.run_code(code, result, async_=asy):\n",
      "  File \"/Users/jinjiewu/anaconda3/lib/python3.11/site-packages/IPython/core/interactiveshell.py\", line 3526, in run_code\n",
      "    exec(code_obj, self.user_global_ns, self.user_ns)\n",
      "  File \"/var/folders/vw/qhm4x34n2tzdd67qh3859yp80000gn/T/ipykernel_3458/2757584945.py\", line 15, in <module>\n",
      "    logger.info(f\"Skipping image_id {image_id} as response already exists.\")\n",
      "Message: 'Skipping image_id DERM_100221.jpg as response already exists.'\n",
      "Arguments: ()\n",
      "--- Logging error ---\n",
      "Traceback (most recent call last):\n",
      "  File \"/Users/jinjiewu/anaconda3/lib/python3.11/logging/__init__.py\", line 1114, in emit\n",
      "    self.flush()\n",
      "  File \"/Users/jinjiewu/anaconda3/lib/python3.11/logging/__init__.py\", line 1094, in flush\n",
      "    self.stream.flush()\n",
      "OSError: [Errno 28] No space left on device\n",
      "Call stack:\n",
      "  File \"<frozen runpy>\", line 198, in _run_module_as_main\n",
      "  File \"<frozen runpy>\", line 88, in _run_code\n",
      "  File \"/Users/jinjiewu/anaconda3/lib/python3.11/site-packages/ipykernel_launcher.py\", line 17, in <module>\n",
      "    app.launch_new_instance()\n",
      "  File \"/Users/jinjiewu/anaconda3/lib/python3.11/site-packages/traitlets/config/application.py\", line 992, in launch_instance\n",
      "    app.start()\n",
      "  File \"/Users/jinjiewu/anaconda3/lib/python3.11/site-packages/ipykernel/kernelapp.py\", line 736, in start\n",
      "    self.io_loop.start()\n",
      "  File \"/Users/jinjiewu/anaconda3/lib/python3.11/site-packages/tornado/platform/asyncio.py\", line 195, in start\n",
      "    self.asyncio_loop.run_forever()\n",
      "  File \"/Users/jinjiewu/anaconda3/lib/python3.11/asyncio/base_events.py\", line 607, in run_forever\n",
      "    self._run_once()\n",
      "  File \"/Users/jinjiewu/anaconda3/lib/python3.11/asyncio/base_events.py\", line 1922, in _run_once\n",
      "    handle._run()\n",
      "  File \"/Users/jinjiewu/anaconda3/lib/python3.11/asyncio/events.py\", line 80, in _run\n",
      "    self._context.run(self._callback, *self._args)\n",
      "  File \"/Users/jinjiewu/anaconda3/lib/python3.11/site-packages/ipykernel/kernelbase.py\", line 516, in dispatch_queue\n",
      "    await self.process_one()\n",
      "  File \"/Users/jinjiewu/anaconda3/lib/python3.11/site-packages/ipykernel/kernelbase.py\", line 505, in process_one\n",
      "    await dispatch(*args)\n",
      "  File \"/Users/jinjiewu/anaconda3/lib/python3.11/site-packages/ipykernel/kernelbase.py\", line 412, in dispatch_shell\n",
      "    await result\n",
      "  File \"/Users/jinjiewu/anaconda3/lib/python3.11/site-packages/ipykernel/kernelbase.py\", line 740, in execute_request\n",
      "    reply_content = await reply_content\n",
      "  File \"/Users/jinjiewu/anaconda3/lib/python3.11/site-packages/ipykernel/ipkernel.py\", line 422, in do_execute\n",
      "    res = shell.run_cell(\n",
      "  File \"/Users/jinjiewu/anaconda3/lib/python3.11/site-packages/ipykernel/zmqshell.py\", line 546, in run_cell\n",
      "    return super().run_cell(*args, **kwargs)\n",
      "  File \"/Users/jinjiewu/anaconda3/lib/python3.11/site-packages/IPython/core/interactiveshell.py\", line 3024, in run_cell\n",
      "    result = self._run_cell(\n",
      "  File \"/Users/jinjiewu/anaconda3/lib/python3.11/site-packages/IPython/core/interactiveshell.py\", line 3079, in _run_cell\n",
      "    result = runner(coro)\n",
      "  File \"/Users/jinjiewu/anaconda3/lib/python3.11/site-packages/IPython/core/async_helpers.py\", line 129, in _pseudo_sync_runner\n",
      "    coro.send(None)\n",
      "  File \"/Users/jinjiewu/anaconda3/lib/python3.11/site-packages/IPython/core/interactiveshell.py\", line 3284, in run_cell_async\n",
      "    has_raised = await self.run_ast_nodes(code_ast.body, cell_name,\n",
      "  File \"/Users/jinjiewu/anaconda3/lib/python3.11/site-packages/IPython/core/interactiveshell.py\", line 3466, in run_ast_nodes\n",
      "    if await self.run_code(code, result, async_=asy):\n",
      "  File \"/Users/jinjiewu/anaconda3/lib/python3.11/site-packages/IPython/core/interactiveshell.py\", line 3526, in run_code\n",
      "    exec(code_obj, self.user_global_ns, self.user_ns)\n",
      "  File \"/var/folders/vw/qhm4x34n2tzdd67qh3859yp80000gn/T/ipykernel_3458/2757584945.py\", line 19, in <module>\n",
      "    result = call_gemini_api(request)\n",
      "  File \"/var/folders/vw/qhm4x34n2tzdd67qh3859yp80000gn/T/ipykernel_3458/388332256.py\", line 15, in call_gemini_api\n",
      "    q1_general_response = api_handler.generate_from_pil_image(pil_image, q1_general)\n",
      "  File \"/Users/jinjiewu/myDermaSynth/DermaSynth/src/gemini_api.py\", line 94, in generate_from_pil_image\n",
      "    response = self.client.models.generate_content(\n",
      "  File \"/Users/jinjiewu/anaconda3/lib/python3.11/site-packages/google/genai/models.py\", line 4934, in generate_content\n",
      "    logger.info(\n",
      "Message: 'AFC is enabled with max remote calls: 10.'\n",
      "Arguments: ()\n",
      "--- Logging error ---\n",
      "Traceback (most recent call last):\n",
      "  File \"/Users/jinjiewu/anaconda3/lib/python3.11/logging/__init__.py\", line 1114, in emit\n",
      "    self.flush()\n",
      "  File \"/Users/jinjiewu/anaconda3/lib/python3.11/logging/__init__.py\", line 1094, in flush\n",
      "    self.stream.flush()\n",
      "OSError: [Errno 28] No space left on device\n",
      "Call stack:\n",
      "  File \"<frozen runpy>\", line 198, in _run_module_as_main\n",
      "  File \"<frozen runpy>\", line 88, in _run_code\n",
      "  File \"/Users/jinjiewu/anaconda3/lib/python3.11/site-packages/ipykernel_launcher.py\", line 17, in <module>\n",
      "    app.launch_new_instance()\n",
      "  File \"/Users/jinjiewu/anaconda3/lib/python3.11/site-packages/traitlets/config/application.py\", line 992, in launch_instance\n",
      "    app.start()\n",
      "  File \"/Users/jinjiewu/anaconda3/lib/python3.11/site-packages/ipykernel/kernelapp.py\", line 736, in start\n",
      "    self.io_loop.start()\n",
      "  File \"/Users/jinjiewu/anaconda3/lib/python3.11/site-packages/tornado/platform/asyncio.py\", line 195, in start\n",
      "    self.asyncio_loop.run_forever()\n",
      "  File \"/Users/jinjiewu/anaconda3/lib/python3.11/asyncio/base_events.py\", line 607, in run_forever\n",
      "    self._run_once()\n",
      "  File \"/Users/jinjiewu/anaconda3/lib/python3.11/asyncio/base_events.py\", line 1922, in _run_once\n",
      "    handle._run()\n",
      "  File \"/Users/jinjiewu/anaconda3/lib/python3.11/asyncio/events.py\", line 80, in _run\n",
      "    self._context.run(self._callback, *self._args)\n",
      "  File \"/Users/jinjiewu/anaconda3/lib/python3.11/site-packages/ipykernel/kernelbase.py\", line 516, in dispatch_queue\n",
      "    await self.process_one()\n",
      "  File \"/Users/jinjiewu/anaconda3/lib/python3.11/site-packages/ipykernel/kernelbase.py\", line 505, in process_one\n",
      "    await dispatch(*args)\n",
      "  File \"/Users/jinjiewu/anaconda3/lib/python3.11/site-packages/ipykernel/kernelbase.py\", line 412, in dispatch_shell\n",
      "    await result\n",
      "  File \"/Users/jinjiewu/anaconda3/lib/python3.11/site-packages/ipykernel/kernelbase.py\", line 740, in execute_request\n",
      "    reply_content = await reply_content\n",
      "  File \"/Users/jinjiewu/anaconda3/lib/python3.11/site-packages/ipykernel/ipkernel.py\", line 422, in do_execute\n",
      "    res = shell.run_cell(\n",
      "  File \"/Users/jinjiewu/anaconda3/lib/python3.11/site-packages/ipykernel/zmqshell.py\", line 546, in run_cell\n",
      "    return super().run_cell(*args, **kwargs)\n",
      "  File \"/Users/jinjiewu/anaconda3/lib/python3.11/site-packages/IPython/core/interactiveshell.py\", line 3024, in run_cell\n",
      "    result = self._run_cell(\n",
      "  File \"/Users/jinjiewu/anaconda3/lib/python3.11/site-packages/IPython/core/interactiveshell.py\", line 3079, in _run_cell\n",
      "    result = runner(coro)\n",
      "  File \"/Users/jinjiewu/anaconda3/lib/python3.11/site-packages/IPython/core/async_helpers.py\", line 129, in _pseudo_sync_runner\n",
      "    coro.send(None)\n",
      "  File \"/Users/jinjiewu/anaconda3/lib/python3.11/site-packages/IPython/core/interactiveshell.py\", line 3284, in run_cell_async\n",
      "    has_raised = await self.run_ast_nodes(code_ast.body, cell_name,\n",
      "  File \"/Users/jinjiewu/anaconda3/lib/python3.11/site-packages/IPython/core/interactiveshell.py\", line 3466, in run_ast_nodes\n",
      "    if await self.run_code(code, result, async_=asy):\n",
      "  File \"/Users/jinjiewu/anaconda3/lib/python3.11/site-packages/IPython/core/interactiveshell.py\", line 3526, in run_code\n",
      "    exec(code_obj, self.user_global_ns, self.user_ns)\n",
      "  File \"/var/folders/vw/qhm4x34n2tzdd67qh3859yp80000gn/T/ipykernel_3458/2757584945.py\", line 19, in <module>\n",
      "    result = call_gemini_api(request)\n",
      "  File \"/var/folders/vw/qhm4x34n2tzdd67qh3859yp80000gn/T/ipykernel_3458/388332256.py\", line 15, in call_gemini_api\n",
      "    q1_general_response = api_handler.generate_from_pil_image(pil_image, q1_general)\n",
      "  File \"/Users/jinjiewu/myDermaSynth/DermaSynth/src/gemini_api.py\", line 94, in generate_from_pil_image\n",
      "    response = self.client.models.generate_content(\n",
      "  File \"/Users/jinjiewu/anaconda3/lib/python3.11/site-packages/google/genai/models.py\", line 4942, in generate_content\n",
      "    response = self._generate_content(\n",
      "  File \"/Users/jinjiewu/anaconda3/lib/python3.11/site-packages/google/genai/models.py\", line 3915, in _generate_content\n",
      "    response_dict = self._api_client.request(\n",
      "  File \"/Users/jinjiewu/anaconda3/lib/python3.11/site-packages/google/genai/_api_client.py\", line 655, in request\n",
      "    response = self._request(http_request, stream=False)\n",
      "  File \"/Users/jinjiewu/anaconda3/lib/python3.11/site-packages/google/genai/_api_client.py\", line 577, in _request\n",
      "    response = self._httpx_client.request(\n",
      "  File \"/Users/jinjiewu/anaconda3/lib/python3.11/site-packages/httpx/_client.py\", line 825, in request\n",
      "    return self.send(request, auth=auth, follow_redirects=follow_redirects)\n",
      "  File \"/Users/jinjiewu/anaconda3/lib/python3.11/site-packages/httpx/_client.py\", line 914, in send\n",
      "    response = self._send_handling_auth(\n",
      "  File \"/Users/jinjiewu/anaconda3/lib/python3.11/site-packages/httpx/_client.py\", line 942, in _send_handling_auth\n",
      "    response = self._send_handling_redirects(\n",
      "  File \"/Users/jinjiewu/anaconda3/lib/python3.11/site-packages/httpx/_client.py\", line 979, in _send_handling_redirects\n",
      "    response = self._send_single_request(request)\n",
      "  File \"/Users/jinjiewu/anaconda3/lib/python3.11/site-packages/httpx/_client.py\", line 1025, in _send_single_request\n",
      "    logger.info(\n",
      "Message: 'HTTP Request: %s %s \"%s %d %s\"'\n",
      "Arguments: ('POST', URL('https://generativelanguage.googleapis.com/v1beta/models/gemini-2.0-flash-exp:generateContent'), 'HTTP/1.1', 200, 'OK')\n",
      "--- Logging error ---\n",
      "Traceback (most recent call last):\n",
      "  File \"/Users/jinjiewu/anaconda3/lib/python3.11/logging/__init__.py\", line 1114, in emit\n",
      "    self.flush()\n",
      "  File \"/Users/jinjiewu/anaconda3/lib/python3.11/logging/__init__.py\", line 1094, in flush\n",
      "    self.stream.flush()\n",
      "OSError: [Errno 28] No space left on device\n",
      "Call stack:\n",
      "  File \"<frozen runpy>\", line 198, in _run_module_as_main\n",
      "  File \"<frozen runpy>\", line 88, in _run_code\n",
      "  File \"/Users/jinjiewu/anaconda3/lib/python3.11/site-packages/ipykernel_launcher.py\", line 17, in <module>\n",
      "    app.launch_new_instance()\n",
      "  File \"/Users/jinjiewu/anaconda3/lib/python3.11/site-packages/traitlets/config/application.py\", line 992, in launch_instance\n",
      "    app.start()\n",
      "  File \"/Users/jinjiewu/anaconda3/lib/python3.11/site-packages/ipykernel/kernelapp.py\", line 736, in start\n",
      "    self.io_loop.start()\n",
      "  File \"/Users/jinjiewu/anaconda3/lib/python3.11/site-packages/tornado/platform/asyncio.py\", line 195, in start\n",
      "    self.asyncio_loop.run_forever()\n",
      "  File \"/Users/jinjiewu/anaconda3/lib/python3.11/asyncio/base_events.py\", line 607, in run_forever\n",
      "    self._run_once()\n",
      "  File \"/Users/jinjiewu/anaconda3/lib/python3.11/asyncio/base_events.py\", line 1922, in _run_once\n",
      "    handle._run()\n",
      "  File \"/Users/jinjiewu/anaconda3/lib/python3.11/asyncio/events.py\", line 80, in _run\n",
      "    self._context.run(self._callback, *self._args)\n",
      "  File \"/Users/jinjiewu/anaconda3/lib/python3.11/site-packages/ipykernel/kernelbase.py\", line 516, in dispatch_queue\n",
      "    await self.process_one()\n",
      "  File \"/Users/jinjiewu/anaconda3/lib/python3.11/site-packages/ipykernel/kernelbase.py\", line 505, in process_one\n",
      "    await dispatch(*args)\n",
      "  File \"/Users/jinjiewu/anaconda3/lib/python3.11/site-packages/ipykernel/kernelbase.py\", line 412, in dispatch_shell\n",
      "    await result\n",
      "  File \"/Users/jinjiewu/anaconda3/lib/python3.11/site-packages/ipykernel/kernelbase.py\", line 740, in execute_request\n",
      "    reply_content = await reply_content\n",
      "  File \"/Users/jinjiewu/anaconda3/lib/python3.11/site-packages/ipykernel/ipkernel.py\", line 422, in do_execute\n",
      "    res = shell.run_cell(\n",
      "  File \"/Users/jinjiewu/anaconda3/lib/python3.11/site-packages/ipykernel/zmqshell.py\", line 546, in run_cell\n",
      "    return super().run_cell(*args, **kwargs)\n",
      "  File \"/Users/jinjiewu/anaconda3/lib/python3.11/site-packages/IPython/core/interactiveshell.py\", line 3024, in run_cell\n",
      "    result = self._run_cell(\n",
      "  File \"/Users/jinjiewu/anaconda3/lib/python3.11/site-packages/IPython/core/interactiveshell.py\", line 3079, in _run_cell\n",
      "    result = runner(coro)\n",
      "  File \"/Users/jinjiewu/anaconda3/lib/python3.11/site-packages/IPython/core/async_helpers.py\", line 129, in _pseudo_sync_runner\n",
      "    coro.send(None)\n",
      "  File \"/Users/jinjiewu/anaconda3/lib/python3.11/site-packages/IPython/core/interactiveshell.py\", line 3284, in run_cell_async\n",
      "    has_raised = await self.run_ast_nodes(code_ast.body, cell_name,\n",
      "  File \"/Users/jinjiewu/anaconda3/lib/python3.11/site-packages/IPython/core/interactiveshell.py\", line 3466, in run_ast_nodes\n",
      "    if await self.run_code(code, result, async_=asy):\n",
      "  File \"/Users/jinjiewu/anaconda3/lib/python3.11/site-packages/IPython/core/interactiveshell.py\", line 3526, in run_code\n",
      "    exec(code_obj, self.user_global_ns, self.user_ns)\n",
      "  File \"/var/folders/vw/qhm4x34n2tzdd67qh3859yp80000gn/T/ipykernel_3458/2757584945.py\", line 19, in <module>\n",
      "    result = call_gemini_api(request)\n",
      "  File \"/var/folders/vw/qhm4x34n2tzdd67qh3859yp80000gn/T/ipykernel_3458/388332256.py\", line 15, in call_gemini_api\n",
      "    q1_general_response = api_handler.generate_from_pil_image(pil_image, q1_general)\n",
      "  File \"/Users/jinjiewu/myDermaSynth/DermaSynth/src/gemini_api.py\", line 94, in generate_from_pil_image\n",
      "    response = self.client.models.generate_content(\n",
      "  File \"/Users/jinjiewu/anaconda3/lib/python3.11/site-packages/google/genai/models.py\", line 4945, in generate_content\n",
      "    logger.info(f'AFC remote call {i} is done.')\n",
      "Message: 'AFC remote call 1 is done.'\n",
      "Arguments: ()\n",
      "--- Logging error ---\n",
      "Traceback (most recent call last):\n",
      "  File \"/Users/jinjiewu/anaconda3/lib/python3.11/logging/__init__.py\", line 1114, in emit\n",
      "    self.flush()\n",
      "  File \"/Users/jinjiewu/anaconda3/lib/python3.11/logging/__init__.py\", line 1094, in flush\n",
      "    self.stream.flush()\n",
      "OSError: [Errno 28] No space left on device\n",
      "Call stack:\n",
      "  File \"<frozen runpy>\", line 198, in _run_module_as_main\n",
      "  File \"<frozen runpy>\", line 88, in _run_code\n",
      "  File \"/Users/jinjiewu/anaconda3/lib/python3.11/site-packages/ipykernel_launcher.py\", line 17, in <module>\n",
      "    app.launch_new_instance()\n",
      "  File \"/Users/jinjiewu/anaconda3/lib/python3.11/site-packages/traitlets/config/application.py\", line 992, in launch_instance\n",
      "    app.start()\n",
      "  File \"/Users/jinjiewu/anaconda3/lib/python3.11/site-packages/ipykernel/kernelapp.py\", line 736, in start\n",
      "    self.io_loop.start()\n",
      "  File \"/Users/jinjiewu/anaconda3/lib/python3.11/site-packages/tornado/platform/asyncio.py\", line 195, in start\n",
      "    self.asyncio_loop.run_forever()\n",
      "  File \"/Users/jinjiewu/anaconda3/lib/python3.11/asyncio/base_events.py\", line 607, in run_forever\n",
      "    self._run_once()\n",
      "  File \"/Users/jinjiewu/anaconda3/lib/python3.11/asyncio/base_events.py\", line 1922, in _run_once\n",
      "    handle._run()\n",
      "  File \"/Users/jinjiewu/anaconda3/lib/python3.11/asyncio/events.py\", line 80, in _run\n",
      "    self._context.run(self._callback, *self._args)\n",
      "  File \"/Users/jinjiewu/anaconda3/lib/python3.11/site-packages/ipykernel/kernelbase.py\", line 516, in dispatch_queue\n",
      "    await self.process_one()\n",
      "  File \"/Users/jinjiewu/anaconda3/lib/python3.11/site-packages/ipykernel/kernelbase.py\", line 505, in process_one\n",
      "    await dispatch(*args)\n",
      "  File \"/Users/jinjiewu/anaconda3/lib/python3.11/site-packages/ipykernel/kernelbase.py\", line 412, in dispatch_shell\n",
      "    await result\n",
      "  File \"/Users/jinjiewu/anaconda3/lib/python3.11/site-packages/ipykernel/kernelbase.py\", line 740, in execute_request\n",
      "    reply_content = await reply_content\n",
      "  File \"/Users/jinjiewu/anaconda3/lib/python3.11/site-packages/ipykernel/ipkernel.py\", line 422, in do_execute\n",
      "    res = shell.run_cell(\n",
      "  File \"/Users/jinjiewu/anaconda3/lib/python3.11/site-packages/ipykernel/zmqshell.py\", line 546, in run_cell\n",
      "    return super().run_cell(*args, **kwargs)\n",
      "  File \"/Users/jinjiewu/anaconda3/lib/python3.11/site-packages/IPython/core/interactiveshell.py\", line 3024, in run_cell\n",
      "    result = self._run_cell(\n",
      "  File \"/Users/jinjiewu/anaconda3/lib/python3.11/site-packages/IPython/core/interactiveshell.py\", line 3079, in _run_cell\n",
      "    result = runner(coro)\n",
      "  File \"/Users/jinjiewu/anaconda3/lib/python3.11/site-packages/IPython/core/async_helpers.py\", line 129, in _pseudo_sync_runner\n",
      "    coro.send(None)\n",
      "  File \"/Users/jinjiewu/anaconda3/lib/python3.11/site-packages/IPython/core/interactiveshell.py\", line 3284, in run_cell_async\n",
      "    has_raised = await self.run_ast_nodes(code_ast.body, cell_name,\n",
      "  File \"/Users/jinjiewu/anaconda3/lib/python3.11/site-packages/IPython/core/interactiveshell.py\", line 3466, in run_ast_nodes\n",
      "    if await self.run_code(code, result, async_=asy):\n",
      "  File \"/Users/jinjiewu/anaconda3/lib/python3.11/site-packages/IPython/core/interactiveshell.py\", line 3526, in run_code\n",
      "    exec(code_obj, self.user_global_ns, self.user_ns)\n",
      "  File \"/var/folders/vw/qhm4x34n2tzdd67qh3859yp80000gn/T/ipykernel_3458/2757584945.py\", line 19, in <module>\n",
      "    result = call_gemini_api(request)\n",
      "  File \"/var/folders/vw/qhm4x34n2tzdd67qh3859yp80000gn/T/ipykernel_3458/388332256.py\", line 17, in call_gemini_api\n",
      "    q2_dataset_response = api_handler.generate_from_pil_image(pil_image, q2_dataset_specific)\n",
      "  File \"/Users/jinjiewu/myDermaSynth/DermaSynth/src/gemini_api.py\", line 94, in generate_from_pil_image\n",
      "    response = self.client.models.generate_content(\n",
      "  File \"/Users/jinjiewu/anaconda3/lib/python3.11/site-packages/google/genai/models.py\", line 4934, in generate_content\n",
      "    logger.info(\n",
      "Message: 'AFC is enabled with max remote calls: 10.'\n",
      "Arguments: ()\n",
      "--- Logging error ---\n",
      "Traceback (most recent call last):\n",
      "  File \"/Users/jinjiewu/anaconda3/lib/python3.11/logging/__init__.py\", line 1114, in emit\n",
      "    self.flush()\n",
      "  File \"/Users/jinjiewu/anaconda3/lib/python3.11/logging/__init__.py\", line 1094, in flush\n",
      "    self.stream.flush()\n",
      "OSError: [Errno 28] No space left on device\n",
      "Call stack:\n",
      "  File \"<frozen runpy>\", line 198, in _run_module_as_main\n",
      "  File \"<frozen runpy>\", line 88, in _run_code\n",
      "  File \"/Users/jinjiewu/anaconda3/lib/python3.11/site-packages/ipykernel_launcher.py\", line 17, in <module>\n",
      "    app.launch_new_instance()\n",
      "  File \"/Users/jinjiewu/anaconda3/lib/python3.11/site-packages/traitlets/config/application.py\", line 992, in launch_instance\n",
      "    app.start()\n",
      "  File \"/Users/jinjiewu/anaconda3/lib/python3.11/site-packages/ipykernel/kernelapp.py\", line 736, in start\n",
      "    self.io_loop.start()\n",
      "  File \"/Users/jinjiewu/anaconda3/lib/python3.11/site-packages/tornado/platform/asyncio.py\", line 195, in start\n",
      "    self.asyncio_loop.run_forever()\n",
      "  File \"/Users/jinjiewu/anaconda3/lib/python3.11/asyncio/base_events.py\", line 607, in run_forever\n",
      "    self._run_once()\n",
      "  File \"/Users/jinjiewu/anaconda3/lib/python3.11/asyncio/base_events.py\", line 1922, in _run_once\n",
      "    handle._run()\n",
      "  File \"/Users/jinjiewu/anaconda3/lib/python3.11/asyncio/events.py\", line 80, in _run\n",
      "    self._context.run(self._callback, *self._args)\n",
      "  File \"/Users/jinjiewu/anaconda3/lib/python3.11/site-packages/ipykernel/kernelbase.py\", line 516, in dispatch_queue\n",
      "    await self.process_one()\n",
      "  File \"/Users/jinjiewu/anaconda3/lib/python3.11/site-packages/ipykernel/kernelbase.py\", line 505, in process_one\n",
      "    await dispatch(*args)\n",
      "  File \"/Users/jinjiewu/anaconda3/lib/python3.11/site-packages/ipykernel/kernelbase.py\", line 412, in dispatch_shell\n",
      "    await result\n",
      "  File \"/Users/jinjiewu/anaconda3/lib/python3.11/site-packages/ipykernel/kernelbase.py\", line 740, in execute_request\n",
      "    reply_content = await reply_content\n",
      "  File \"/Users/jinjiewu/anaconda3/lib/python3.11/site-packages/ipykernel/ipkernel.py\", line 422, in do_execute\n",
      "    res = shell.run_cell(\n",
      "  File \"/Users/jinjiewu/anaconda3/lib/python3.11/site-packages/ipykernel/zmqshell.py\", line 546, in run_cell\n",
      "    return super().run_cell(*args, **kwargs)\n",
      "  File \"/Users/jinjiewu/anaconda3/lib/python3.11/site-packages/IPython/core/interactiveshell.py\", line 3024, in run_cell\n",
      "    result = self._run_cell(\n",
      "  File \"/Users/jinjiewu/anaconda3/lib/python3.11/site-packages/IPython/core/interactiveshell.py\", line 3079, in _run_cell\n",
      "    result = runner(coro)\n",
      "  File \"/Users/jinjiewu/anaconda3/lib/python3.11/site-packages/IPython/core/async_helpers.py\", line 129, in _pseudo_sync_runner\n",
      "    coro.send(None)\n",
      "  File \"/Users/jinjiewu/anaconda3/lib/python3.11/site-packages/IPython/core/interactiveshell.py\", line 3284, in run_cell_async\n",
      "    has_raised = await self.run_ast_nodes(code_ast.body, cell_name,\n",
      "  File \"/Users/jinjiewu/anaconda3/lib/python3.11/site-packages/IPython/core/interactiveshell.py\", line 3466, in run_ast_nodes\n",
      "    if await self.run_code(code, result, async_=asy):\n",
      "  File \"/Users/jinjiewu/anaconda3/lib/python3.11/site-packages/IPython/core/interactiveshell.py\", line 3526, in run_code\n",
      "    exec(code_obj, self.user_global_ns, self.user_ns)\n",
      "  File \"/var/folders/vw/qhm4x34n2tzdd67qh3859yp80000gn/T/ipykernel_3458/2757584945.py\", line 19, in <module>\n",
      "    result = call_gemini_api(request)\n",
      "  File \"/var/folders/vw/qhm4x34n2tzdd67qh3859yp80000gn/T/ipykernel_3458/388332256.py\", line 17, in call_gemini_api\n",
      "    q2_dataset_response = api_handler.generate_from_pil_image(pil_image, q2_dataset_specific)\n",
      "  File \"/Users/jinjiewu/myDermaSynth/DermaSynth/src/gemini_api.py\", line 94, in generate_from_pil_image\n",
      "    response = self.client.models.generate_content(\n",
      "  File \"/Users/jinjiewu/anaconda3/lib/python3.11/site-packages/google/genai/models.py\", line 4942, in generate_content\n",
      "    response = self._generate_content(\n",
      "  File \"/Users/jinjiewu/anaconda3/lib/python3.11/site-packages/google/genai/models.py\", line 3915, in _generate_content\n",
      "    response_dict = self._api_client.request(\n",
      "  File \"/Users/jinjiewu/anaconda3/lib/python3.11/site-packages/google/genai/_api_client.py\", line 655, in request\n",
      "    response = self._request(http_request, stream=False)\n",
      "  File \"/Users/jinjiewu/anaconda3/lib/python3.11/site-packages/google/genai/_api_client.py\", line 577, in _request\n",
      "    response = self._httpx_client.request(\n",
      "  File \"/Users/jinjiewu/anaconda3/lib/python3.11/site-packages/httpx/_client.py\", line 825, in request\n",
      "    return self.send(request, auth=auth, follow_redirects=follow_redirects)\n",
      "  File \"/Users/jinjiewu/anaconda3/lib/python3.11/site-packages/httpx/_client.py\", line 914, in send\n",
      "    response = self._send_handling_auth(\n",
      "  File \"/Users/jinjiewu/anaconda3/lib/python3.11/site-packages/httpx/_client.py\", line 942, in _send_handling_auth\n",
      "    response = self._send_handling_redirects(\n",
      "  File \"/Users/jinjiewu/anaconda3/lib/python3.11/site-packages/httpx/_client.py\", line 979, in _send_handling_redirects\n",
      "    response = self._send_single_request(request)\n",
      "  File \"/Users/jinjiewu/anaconda3/lib/python3.11/site-packages/httpx/_client.py\", line 1025, in _send_single_request\n",
      "    logger.info(\n",
      "Message: 'HTTP Request: %s %s \"%s %d %s\"'\n",
      "Arguments: ('POST', URL('https://generativelanguage.googleapis.com/v1beta/models/gemini-2.0-flash-exp:generateContent'), 'HTTP/1.1', 200, 'OK')\n",
      "--- Logging error ---\n",
      "Traceback (most recent call last):\n",
      "  File \"/Users/jinjiewu/anaconda3/lib/python3.11/logging/__init__.py\", line 1114, in emit\n",
      "    self.flush()\n",
      "  File \"/Users/jinjiewu/anaconda3/lib/python3.11/logging/__init__.py\", line 1094, in flush\n",
      "    self.stream.flush()\n",
      "OSError: [Errno 28] No space left on device\n",
      "Call stack:\n",
      "  File \"<frozen runpy>\", line 198, in _run_module_as_main\n",
      "  File \"<frozen runpy>\", line 88, in _run_code\n",
      "  File \"/Users/jinjiewu/anaconda3/lib/python3.11/site-packages/ipykernel_launcher.py\", line 17, in <module>\n",
      "    app.launch_new_instance()\n",
      "  File \"/Users/jinjiewu/anaconda3/lib/python3.11/site-packages/traitlets/config/application.py\", line 992, in launch_instance\n",
      "    app.start()\n",
      "  File \"/Users/jinjiewu/anaconda3/lib/python3.11/site-packages/ipykernel/kernelapp.py\", line 736, in start\n",
      "    self.io_loop.start()\n",
      "  File \"/Users/jinjiewu/anaconda3/lib/python3.11/site-packages/tornado/platform/asyncio.py\", line 195, in start\n",
      "    self.asyncio_loop.run_forever()\n",
      "  File \"/Users/jinjiewu/anaconda3/lib/python3.11/asyncio/base_events.py\", line 607, in run_forever\n",
      "    self._run_once()\n",
      "  File \"/Users/jinjiewu/anaconda3/lib/python3.11/asyncio/base_events.py\", line 1922, in _run_once\n",
      "    handle._run()\n",
      "  File \"/Users/jinjiewu/anaconda3/lib/python3.11/asyncio/events.py\", line 80, in _run\n",
      "    self._context.run(self._callback, *self._args)\n",
      "  File \"/Users/jinjiewu/anaconda3/lib/python3.11/site-packages/ipykernel/kernelbase.py\", line 516, in dispatch_queue\n",
      "    await self.process_one()\n",
      "  File \"/Users/jinjiewu/anaconda3/lib/python3.11/site-packages/ipykernel/kernelbase.py\", line 505, in process_one\n",
      "    await dispatch(*args)\n",
      "  File \"/Users/jinjiewu/anaconda3/lib/python3.11/site-packages/ipykernel/kernelbase.py\", line 412, in dispatch_shell\n",
      "    await result\n",
      "  File \"/Users/jinjiewu/anaconda3/lib/python3.11/site-packages/ipykernel/kernelbase.py\", line 740, in execute_request\n",
      "    reply_content = await reply_content\n",
      "  File \"/Users/jinjiewu/anaconda3/lib/python3.11/site-packages/ipykernel/ipkernel.py\", line 422, in do_execute\n",
      "    res = shell.run_cell(\n",
      "  File \"/Users/jinjiewu/anaconda3/lib/python3.11/site-packages/ipykernel/zmqshell.py\", line 546, in run_cell\n",
      "    return super().run_cell(*args, **kwargs)\n",
      "  File \"/Users/jinjiewu/anaconda3/lib/python3.11/site-packages/IPython/core/interactiveshell.py\", line 3024, in run_cell\n",
      "    result = self._run_cell(\n",
      "  File \"/Users/jinjiewu/anaconda3/lib/python3.11/site-packages/IPython/core/interactiveshell.py\", line 3079, in _run_cell\n",
      "    result = runner(coro)\n",
      "  File \"/Users/jinjiewu/anaconda3/lib/python3.11/site-packages/IPython/core/async_helpers.py\", line 129, in _pseudo_sync_runner\n",
      "    coro.send(None)\n",
      "  File \"/Users/jinjiewu/anaconda3/lib/python3.11/site-packages/IPython/core/interactiveshell.py\", line 3284, in run_cell_async\n",
      "    has_raised = await self.run_ast_nodes(code_ast.body, cell_name,\n",
      "  File \"/Users/jinjiewu/anaconda3/lib/python3.11/site-packages/IPython/core/interactiveshell.py\", line 3466, in run_ast_nodes\n",
      "    if await self.run_code(code, result, async_=asy):\n",
      "  File \"/Users/jinjiewu/anaconda3/lib/python3.11/site-packages/IPython/core/interactiveshell.py\", line 3526, in run_code\n",
      "    exec(code_obj, self.user_global_ns, self.user_ns)\n",
      "  File \"/var/folders/vw/qhm4x34n2tzdd67qh3859yp80000gn/T/ipykernel_3458/2757584945.py\", line 19, in <module>\n",
      "    result = call_gemini_api(request)\n",
      "  File \"/var/folders/vw/qhm4x34n2tzdd67qh3859yp80000gn/T/ipykernel_3458/388332256.py\", line 17, in call_gemini_api\n",
      "    q2_dataset_response = api_handler.generate_from_pil_image(pil_image, q2_dataset_specific)\n",
      "  File \"/Users/jinjiewu/myDermaSynth/DermaSynth/src/gemini_api.py\", line 94, in generate_from_pil_image\n",
      "    response = self.client.models.generate_content(\n",
      "  File \"/Users/jinjiewu/anaconda3/lib/python3.11/site-packages/google/genai/models.py\", line 4945, in generate_content\n",
      "    logger.info(f'AFC remote call {i} is done.')\n",
      "Message: 'AFC remote call 1 is done.'\n",
      "Arguments: ()\n",
      "--- Logging error ---\n",
      "Traceback (most recent call last):\n",
      "  File \"/var/folders/vw/qhm4x34n2tzdd67qh3859yp80000gn/T/ipykernel_3458/2757584945.py\", line 21, in <module>\n",
      "    with open(generated_response_file, \"w\") as out_file:\n",
      "         ^^^^^^^^^^^^^^^^^^^^^^^^^^^^^^^^^^\n",
      "  File \"/Users/jinjiewu/anaconda3/lib/python3.11/site-packages/IPython/core/interactiveshell.py\", line 286, in _modified_open\n",
      "    return io_open(file, *args, **kwargs)\n",
      "           ^^^^^^^^^^^^^^^^^^^^^^^^^^^^^^\n",
      "OSError: [Errno 28] No space left on device: '../api_results/derm12345/DERM_100235.jpg_response.json'\n",
      "\n",
      "During handling of the above exception, another exception occurred:\n",
      "\n",
      "Traceback (most recent call last):\n",
      "  File \"/Users/jinjiewu/anaconda3/lib/python3.11/logging/__init__.py\", line 1114, in emit\n",
      "    self.flush()\n",
      "  File \"/Users/jinjiewu/anaconda3/lib/python3.11/logging/__init__.py\", line 1094, in flush\n",
      "    self.stream.flush()\n",
      "OSError: [Errno 28] No space left on device\n",
      "Call stack:\n",
      "  File \"<frozen runpy>\", line 198, in _run_module_as_main\n",
      "  File \"<frozen runpy>\", line 88, in _run_code\n",
      "  File \"/Users/jinjiewu/anaconda3/lib/python3.11/site-packages/ipykernel_launcher.py\", line 17, in <module>\n",
      "    app.launch_new_instance()\n",
      "  File \"/Users/jinjiewu/anaconda3/lib/python3.11/site-packages/traitlets/config/application.py\", line 992, in launch_instance\n",
      "    app.start()\n",
      "  File \"/Users/jinjiewu/anaconda3/lib/python3.11/site-packages/ipykernel/kernelapp.py\", line 736, in start\n",
      "    self.io_loop.start()\n",
      "  File \"/Users/jinjiewu/anaconda3/lib/python3.11/site-packages/tornado/platform/asyncio.py\", line 195, in start\n",
      "    self.asyncio_loop.run_forever()\n",
      "  File \"/Users/jinjiewu/anaconda3/lib/python3.11/asyncio/base_events.py\", line 607, in run_forever\n",
      "    self._run_once()\n",
      "  File \"/Users/jinjiewu/anaconda3/lib/python3.11/asyncio/base_events.py\", line 1922, in _run_once\n",
      "    handle._run()\n",
      "  File \"/Users/jinjiewu/anaconda3/lib/python3.11/asyncio/events.py\", line 80, in _run\n",
      "    self._context.run(self._callback, *self._args)\n",
      "  File \"/Users/jinjiewu/anaconda3/lib/python3.11/site-packages/ipykernel/kernelbase.py\", line 516, in dispatch_queue\n",
      "    await self.process_one()\n",
      "  File \"/Users/jinjiewu/anaconda3/lib/python3.11/site-packages/ipykernel/kernelbase.py\", line 505, in process_one\n",
      "    await dispatch(*args)\n",
      "  File \"/Users/jinjiewu/anaconda3/lib/python3.11/site-packages/ipykernel/kernelbase.py\", line 412, in dispatch_shell\n",
      "    await result\n",
      "  File \"/Users/jinjiewu/anaconda3/lib/python3.11/site-packages/ipykernel/kernelbase.py\", line 740, in execute_request\n",
      "    reply_content = await reply_content\n",
      "  File \"/Users/jinjiewu/anaconda3/lib/python3.11/site-packages/ipykernel/ipkernel.py\", line 422, in do_execute\n",
      "    res = shell.run_cell(\n",
      "  File \"/Users/jinjiewu/anaconda3/lib/python3.11/site-packages/ipykernel/zmqshell.py\", line 546, in run_cell\n",
      "    return super().run_cell(*args, **kwargs)\n",
      "  File \"/Users/jinjiewu/anaconda3/lib/python3.11/site-packages/IPython/core/interactiveshell.py\", line 3024, in run_cell\n",
      "    result = self._run_cell(\n",
      "  File \"/Users/jinjiewu/anaconda3/lib/python3.11/site-packages/IPython/core/interactiveshell.py\", line 3079, in _run_cell\n",
      "    result = runner(coro)\n",
      "  File \"/Users/jinjiewu/anaconda3/lib/python3.11/site-packages/IPython/core/async_helpers.py\", line 129, in _pseudo_sync_runner\n",
      "    coro.send(None)\n",
      "  File \"/Users/jinjiewu/anaconda3/lib/python3.11/site-packages/IPython/core/interactiveshell.py\", line 3284, in run_cell_async\n",
      "    has_raised = await self.run_ast_nodes(code_ast.body, cell_name,\n",
      "  File \"/Users/jinjiewu/anaconda3/lib/python3.11/site-packages/IPython/core/interactiveshell.py\", line 3466, in run_ast_nodes\n",
      "    if await self.run_code(code, result, async_=asy):\n",
      "  File \"/Users/jinjiewu/anaconda3/lib/python3.11/site-packages/IPython/core/interactiveshell.py\", line 3526, in run_code\n",
      "    exec(code_obj, self.user_global_ns, self.user_ns)\n",
      "  File \"/var/folders/vw/qhm4x34n2tzdd67qh3859yp80000gn/T/ipykernel_3458/2757584945.py\", line 26, in <module>\n",
      "    logger.warning(f\"Error processing image_id {image_id}: {e}\")\n",
      "Message: \"Error processing image_id DERM_100235.jpg: [Errno 28] No space left on device: '../api_results/derm12345/DERM_100235.jpg_response.json'\"\n",
      "Arguments: ()\n",
      "--- Logging error ---\n",
      "Traceback (most recent call last):\n",
      "  File \"/Users/jinjiewu/anaconda3/lib/python3.11/logging/__init__.py\", line 1114, in emit\n",
      "    self.flush()\n",
      "  File \"/Users/jinjiewu/anaconda3/lib/python3.11/logging/__init__.py\", line 1094, in flush\n",
      "    self.stream.flush()\n",
      "OSError: [Errno 28] No space left on device\n",
      "Call stack:\n",
      "  File \"<frozen runpy>\", line 198, in _run_module_as_main\n",
      "  File \"<frozen runpy>\", line 88, in _run_code\n",
      "  File \"/Users/jinjiewu/anaconda3/lib/python3.11/site-packages/ipykernel_launcher.py\", line 17, in <module>\n",
      "    app.launch_new_instance()\n",
      "  File \"/Users/jinjiewu/anaconda3/lib/python3.11/site-packages/traitlets/config/application.py\", line 992, in launch_instance\n",
      "    app.start()\n",
      "  File \"/Users/jinjiewu/anaconda3/lib/python3.11/site-packages/ipykernel/kernelapp.py\", line 736, in start\n",
      "    self.io_loop.start()\n",
      "  File \"/Users/jinjiewu/anaconda3/lib/python3.11/site-packages/tornado/platform/asyncio.py\", line 195, in start\n",
      "    self.asyncio_loop.run_forever()\n",
      "  File \"/Users/jinjiewu/anaconda3/lib/python3.11/asyncio/base_events.py\", line 607, in run_forever\n",
      "    self._run_once()\n",
      "  File \"/Users/jinjiewu/anaconda3/lib/python3.11/asyncio/base_events.py\", line 1922, in _run_once\n",
      "    handle._run()\n",
      "  File \"/Users/jinjiewu/anaconda3/lib/python3.11/asyncio/events.py\", line 80, in _run\n",
      "    self._context.run(self._callback, *self._args)\n",
      "  File \"/Users/jinjiewu/anaconda3/lib/python3.11/site-packages/ipykernel/kernelbase.py\", line 516, in dispatch_queue\n",
      "    await self.process_one()\n",
      "  File \"/Users/jinjiewu/anaconda3/lib/python3.11/site-packages/ipykernel/kernelbase.py\", line 505, in process_one\n",
      "    await dispatch(*args)\n",
      "  File \"/Users/jinjiewu/anaconda3/lib/python3.11/site-packages/ipykernel/kernelbase.py\", line 412, in dispatch_shell\n",
      "    await result\n",
      "  File \"/Users/jinjiewu/anaconda3/lib/python3.11/site-packages/ipykernel/kernelbase.py\", line 740, in execute_request\n",
      "    reply_content = await reply_content\n",
      "  File \"/Users/jinjiewu/anaconda3/lib/python3.11/site-packages/ipykernel/ipkernel.py\", line 422, in do_execute\n",
      "    res = shell.run_cell(\n",
      "  File \"/Users/jinjiewu/anaconda3/lib/python3.11/site-packages/ipykernel/zmqshell.py\", line 546, in run_cell\n",
      "    return super().run_cell(*args, **kwargs)\n",
      "  File \"/Users/jinjiewu/anaconda3/lib/python3.11/site-packages/IPython/core/interactiveshell.py\", line 3024, in run_cell\n",
      "    result = self._run_cell(\n",
      "  File \"/Users/jinjiewu/anaconda3/lib/python3.11/site-packages/IPython/core/interactiveshell.py\", line 3079, in _run_cell\n",
      "    result = runner(coro)\n",
      "  File \"/Users/jinjiewu/anaconda3/lib/python3.11/site-packages/IPython/core/async_helpers.py\", line 129, in _pseudo_sync_runner\n",
      "    coro.send(None)\n",
      "  File \"/Users/jinjiewu/anaconda3/lib/python3.11/site-packages/IPython/core/interactiveshell.py\", line 3284, in run_cell_async\n",
      "    has_raised = await self.run_ast_nodes(code_ast.body, cell_name,\n",
      "  File \"/Users/jinjiewu/anaconda3/lib/python3.11/site-packages/IPython/core/interactiveshell.py\", line 3466, in run_ast_nodes\n",
      "    if await self.run_code(code, result, async_=asy):\n",
      "  File \"/Users/jinjiewu/anaconda3/lib/python3.11/site-packages/IPython/core/interactiveshell.py\", line 3526, in run_code\n",
      "    exec(code_obj, self.user_global_ns, self.user_ns)\n",
      "  File \"/var/folders/vw/qhm4x34n2tzdd67qh3859yp80000gn/T/ipykernel_3458/2757584945.py\", line 15, in <module>\n",
      "    logger.info(f\"Skipping image_id {image_id} as response already exists.\")\n",
      "Message: 'Skipping image_id DERM_100308.jpg as response already exists.'\n",
      "Arguments: ()\n",
      "--- Logging error ---\n",
      "Traceback (most recent call last):\n",
      "  File \"/Users/jinjiewu/anaconda3/lib/python3.11/logging/__init__.py\", line 1114, in emit\n",
      "    self.flush()\n",
      "  File \"/Users/jinjiewu/anaconda3/lib/python3.11/logging/__init__.py\", line 1094, in flush\n",
      "    self.stream.flush()\n",
      "OSError: [Errno 28] No space left on device\n",
      "Call stack:\n",
      "  File \"<frozen runpy>\", line 198, in _run_module_as_main\n",
      "  File \"<frozen runpy>\", line 88, in _run_code\n",
      "  File \"/Users/jinjiewu/anaconda3/lib/python3.11/site-packages/ipykernel_launcher.py\", line 17, in <module>\n",
      "    app.launch_new_instance()\n",
      "  File \"/Users/jinjiewu/anaconda3/lib/python3.11/site-packages/traitlets/config/application.py\", line 992, in launch_instance\n",
      "    app.start()\n",
      "  File \"/Users/jinjiewu/anaconda3/lib/python3.11/site-packages/ipykernel/kernelapp.py\", line 736, in start\n",
      "    self.io_loop.start()\n",
      "  File \"/Users/jinjiewu/anaconda3/lib/python3.11/site-packages/tornado/platform/asyncio.py\", line 195, in start\n",
      "    self.asyncio_loop.run_forever()\n",
      "  File \"/Users/jinjiewu/anaconda3/lib/python3.11/asyncio/base_events.py\", line 607, in run_forever\n",
      "    self._run_once()\n",
      "  File \"/Users/jinjiewu/anaconda3/lib/python3.11/asyncio/base_events.py\", line 1922, in _run_once\n",
      "    handle._run()\n",
      "  File \"/Users/jinjiewu/anaconda3/lib/python3.11/asyncio/events.py\", line 80, in _run\n",
      "    self._context.run(self._callback, *self._args)\n",
      "  File \"/Users/jinjiewu/anaconda3/lib/python3.11/site-packages/ipykernel/kernelbase.py\", line 516, in dispatch_queue\n",
      "    await self.process_one()\n",
      "  File \"/Users/jinjiewu/anaconda3/lib/python3.11/site-packages/ipykernel/kernelbase.py\", line 505, in process_one\n",
      "    await dispatch(*args)\n",
      "  File \"/Users/jinjiewu/anaconda3/lib/python3.11/site-packages/ipykernel/kernelbase.py\", line 412, in dispatch_shell\n",
      "    await result\n",
      "  File \"/Users/jinjiewu/anaconda3/lib/python3.11/site-packages/ipykernel/kernelbase.py\", line 740, in execute_request\n",
      "    reply_content = await reply_content\n",
      "  File \"/Users/jinjiewu/anaconda3/lib/python3.11/site-packages/ipykernel/ipkernel.py\", line 422, in do_execute\n",
      "    res = shell.run_cell(\n",
      "  File \"/Users/jinjiewu/anaconda3/lib/python3.11/site-packages/ipykernel/zmqshell.py\", line 546, in run_cell\n",
      "    return super().run_cell(*args, **kwargs)\n",
      "  File \"/Users/jinjiewu/anaconda3/lib/python3.11/site-packages/IPython/core/interactiveshell.py\", line 3024, in run_cell\n",
      "    result = self._run_cell(\n",
      "  File \"/Users/jinjiewu/anaconda3/lib/python3.11/site-packages/IPython/core/interactiveshell.py\", line 3079, in _run_cell\n",
      "    result = runner(coro)\n",
      "  File \"/Users/jinjiewu/anaconda3/lib/python3.11/site-packages/IPython/core/async_helpers.py\", line 129, in _pseudo_sync_runner\n",
      "    coro.send(None)\n",
      "  File \"/Users/jinjiewu/anaconda3/lib/python3.11/site-packages/IPython/core/interactiveshell.py\", line 3284, in run_cell_async\n",
      "    has_raised = await self.run_ast_nodes(code_ast.body, cell_name,\n",
      "  File \"/Users/jinjiewu/anaconda3/lib/python3.11/site-packages/IPython/core/interactiveshell.py\", line 3466, in run_ast_nodes\n",
      "    if await self.run_code(code, result, async_=asy):\n",
      "  File \"/Users/jinjiewu/anaconda3/lib/python3.11/site-packages/IPython/core/interactiveshell.py\", line 3526, in run_code\n",
      "    exec(code_obj, self.user_global_ns, self.user_ns)\n",
      "  File \"/var/folders/vw/qhm4x34n2tzdd67qh3859yp80000gn/T/ipykernel_3458/2757584945.py\", line 15, in <module>\n",
      "    logger.info(f\"Skipping image_id {image_id} as response already exists.\")\n",
      "Message: 'Skipping image_id DERM_100533.jpg as response already exists.'\n",
      "Arguments: ()\n",
      "--- Logging error ---\n",
      "Traceback (most recent call last):\n",
      "  File \"/Users/jinjiewu/anaconda3/lib/python3.11/logging/__init__.py\", line 1114, in emit\n",
      "    self.flush()\n",
      "  File \"/Users/jinjiewu/anaconda3/lib/python3.11/logging/__init__.py\", line 1094, in flush\n",
      "    self.stream.flush()\n",
      "OSError: [Errno 28] No space left on device\n",
      "Call stack:\n",
      "  File \"<frozen runpy>\", line 198, in _run_module_as_main\n",
      "  File \"<frozen runpy>\", line 88, in _run_code\n",
      "  File \"/Users/jinjiewu/anaconda3/lib/python3.11/site-packages/ipykernel_launcher.py\", line 17, in <module>\n",
      "    app.launch_new_instance()\n",
      "  File \"/Users/jinjiewu/anaconda3/lib/python3.11/site-packages/traitlets/config/application.py\", line 992, in launch_instance\n",
      "    app.start()\n",
      "  File \"/Users/jinjiewu/anaconda3/lib/python3.11/site-packages/ipykernel/kernelapp.py\", line 736, in start\n",
      "    self.io_loop.start()\n",
      "  File \"/Users/jinjiewu/anaconda3/lib/python3.11/site-packages/tornado/platform/asyncio.py\", line 195, in start\n",
      "    self.asyncio_loop.run_forever()\n",
      "  File \"/Users/jinjiewu/anaconda3/lib/python3.11/asyncio/base_events.py\", line 607, in run_forever\n",
      "    self._run_once()\n",
      "  File \"/Users/jinjiewu/anaconda3/lib/python3.11/asyncio/base_events.py\", line 1922, in _run_once\n",
      "    handle._run()\n",
      "  File \"/Users/jinjiewu/anaconda3/lib/python3.11/asyncio/events.py\", line 80, in _run\n",
      "    self._context.run(self._callback, *self._args)\n",
      "  File \"/Users/jinjiewu/anaconda3/lib/python3.11/site-packages/ipykernel/kernelbase.py\", line 516, in dispatch_queue\n",
      "    await self.process_one()\n",
      "  File \"/Users/jinjiewu/anaconda3/lib/python3.11/site-packages/ipykernel/kernelbase.py\", line 505, in process_one\n",
      "    await dispatch(*args)\n",
      "  File \"/Users/jinjiewu/anaconda3/lib/python3.11/site-packages/ipykernel/kernelbase.py\", line 412, in dispatch_shell\n",
      "    await result\n",
      "  File \"/Users/jinjiewu/anaconda3/lib/python3.11/site-packages/ipykernel/kernelbase.py\", line 740, in execute_request\n",
      "    reply_content = await reply_content\n",
      "  File \"/Users/jinjiewu/anaconda3/lib/python3.11/site-packages/ipykernel/ipkernel.py\", line 422, in do_execute\n",
      "    res = shell.run_cell(\n",
      "  File \"/Users/jinjiewu/anaconda3/lib/python3.11/site-packages/ipykernel/zmqshell.py\", line 546, in run_cell\n",
      "    return super().run_cell(*args, **kwargs)\n",
      "  File \"/Users/jinjiewu/anaconda3/lib/python3.11/site-packages/IPython/core/interactiveshell.py\", line 3024, in run_cell\n",
      "    result = self._run_cell(\n",
      "  File \"/Users/jinjiewu/anaconda3/lib/python3.11/site-packages/IPython/core/interactiveshell.py\", line 3079, in _run_cell\n",
      "    result = runner(coro)\n",
      "  File \"/Users/jinjiewu/anaconda3/lib/python3.11/site-packages/IPython/core/async_helpers.py\", line 129, in _pseudo_sync_runner\n",
      "    coro.send(None)\n",
      "  File \"/Users/jinjiewu/anaconda3/lib/python3.11/site-packages/IPython/core/interactiveshell.py\", line 3284, in run_cell_async\n",
      "    has_raised = await self.run_ast_nodes(code_ast.body, cell_name,\n",
      "  File \"/Users/jinjiewu/anaconda3/lib/python3.11/site-packages/IPython/core/interactiveshell.py\", line 3466, in run_ast_nodes\n",
      "    if await self.run_code(code, result, async_=asy):\n",
      "  File \"/Users/jinjiewu/anaconda3/lib/python3.11/site-packages/IPython/core/interactiveshell.py\", line 3526, in run_code\n",
      "    exec(code_obj, self.user_global_ns, self.user_ns)\n",
      "  File \"/var/folders/vw/qhm4x34n2tzdd67qh3859yp80000gn/T/ipykernel_3458/2757584945.py\", line 15, in <module>\n",
      "    logger.info(f\"Skipping image_id {image_id} as response already exists.\")\n",
      "Message: 'Skipping image_id DERM_100652.jpg as response already exists.'\n",
      "Arguments: ()\n",
      "--- Logging error ---\n",
      "Traceback (most recent call last):\n",
      "  File \"/Users/jinjiewu/anaconda3/lib/python3.11/logging/__init__.py\", line 1114, in emit\n",
      "    self.flush()\n",
      "  File \"/Users/jinjiewu/anaconda3/lib/python3.11/logging/__init__.py\", line 1094, in flush\n",
      "    self.stream.flush()\n",
      "OSError: [Errno 28] No space left on device\n",
      "Call stack:\n",
      "  File \"<frozen runpy>\", line 198, in _run_module_as_main\n",
      "  File \"<frozen runpy>\", line 88, in _run_code\n",
      "  File \"/Users/jinjiewu/anaconda3/lib/python3.11/site-packages/ipykernel_launcher.py\", line 17, in <module>\n",
      "    app.launch_new_instance()\n",
      "  File \"/Users/jinjiewu/anaconda3/lib/python3.11/site-packages/traitlets/config/application.py\", line 992, in launch_instance\n",
      "    app.start()\n",
      "  File \"/Users/jinjiewu/anaconda3/lib/python3.11/site-packages/ipykernel/kernelapp.py\", line 736, in start\n",
      "    self.io_loop.start()\n",
      "  File \"/Users/jinjiewu/anaconda3/lib/python3.11/site-packages/tornado/platform/asyncio.py\", line 195, in start\n",
      "    self.asyncio_loop.run_forever()\n",
      "  File \"/Users/jinjiewu/anaconda3/lib/python3.11/asyncio/base_events.py\", line 607, in run_forever\n",
      "    self._run_once()\n",
      "  File \"/Users/jinjiewu/anaconda3/lib/python3.11/asyncio/base_events.py\", line 1922, in _run_once\n",
      "    handle._run()\n",
      "  File \"/Users/jinjiewu/anaconda3/lib/python3.11/asyncio/events.py\", line 80, in _run\n",
      "    self._context.run(self._callback, *self._args)\n",
      "  File \"/Users/jinjiewu/anaconda3/lib/python3.11/site-packages/ipykernel/kernelbase.py\", line 516, in dispatch_queue\n",
      "    await self.process_one()\n",
      "  File \"/Users/jinjiewu/anaconda3/lib/python3.11/site-packages/ipykernel/kernelbase.py\", line 505, in process_one\n",
      "    await dispatch(*args)\n",
      "  File \"/Users/jinjiewu/anaconda3/lib/python3.11/site-packages/ipykernel/kernelbase.py\", line 412, in dispatch_shell\n",
      "    await result\n",
      "  File \"/Users/jinjiewu/anaconda3/lib/python3.11/site-packages/ipykernel/kernelbase.py\", line 740, in execute_request\n",
      "    reply_content = await reply_content\n",
      "  File \"/Users/jinjiewu/anaconda3/lib/python3.11/site-packages/ipykernel/ipkernel.py\", line 422, in do_execute\n",
      "    res = shell.run_cell(\n",
      "  File \"/Users/jinjiewu/anaconda3/lib/python3.11/site-packages/ipykernel/zmqshell.py\", line 546, in run_cell\n",
      "    return super().run_cell(*args, **kwargs)\n",
      "  File \"/Users/jinjiewu/anaconda3/lib/python3.11/site-packages/IPython/core/interactiveshell.py\", line 3024, in run_cell\n",
      "    result = self._run_cell(\n",
      "  File \"/Users/jinjiewu/anaconda3/lib/python3.11/site-packages/IPython/core/interactiveshell.py\", line 3079, in _run_cell\n",
      "    result = runner(coro)\n",
      "  File \"/Users/jinjiewu/anaconda3/lib/python3.11/site-packages/IPython/core/async_helpers.py\", line 129, in _pseudo_sync_runner\n",
      "    coro.send(None)\n",
      "  File \"/Users/jinjiewu/anaconda3/lib/python3.11/site-packages/IPython/core/interactiveshell.py\", line 3284, in run_cell_async\n",
      "    has_raised = await self.run_ast_nodes(code_ast.body, cell_name,\n",
      "  File \"/Users/jinjiewu/anaconda3/lib/python3.11/site-packages/IPython/core/interactiveshell.py\", line 3466, in run_ast_nodes\n",
      "    if await self.run_code(code, result, async_=asy):\n",
      "  File \"/Users/jinjiewu/anaconda3/lib/python3.11/site-packages/IPython/core/interactiveshell.py\", line 3526, in run_code\n",
      "    exec(code_obj, self.user_global_ns, self.user_ns)\n",
      "  File \"/var/folders/vw/qhm4x34n2tzdd67qh3859yp80000gn/T/ipykernel_3458/2757584945.py\", line 15, in <module>\n",
      "    logger.info(f\"Skipping image_id {image_id} as response already exists.\")\n",
      "Message: 'Skipping image_id DERM_100735.jpg as response already exists.'\n",
      "Arguments: ()\n",
      "--- Logging error ---\n",
      "Traceback (most recent call last):\n",
      "  File \"/Users/jinjiewu/anaconda3/lib/python3.11/logging/__init__.py\", line 1114, in emit\n",
      "    self.flush()\n",
      "  File \"/Users/jinjiewu/anaconda3/lib/python3.11/logging/__init__.py\", line 1094, in flush\n",
      "    self.stream.flush()\n",
      "OSError: [Errno 28] No space left on device\n",
      "Call stack:\n",
      "  File \"<frozen runpy>\", line 198, in _run_module_as_main\n",
      "  File \"<frozen runpy>\", line 88, in _run_code\n",
      "  File \"/Users/jinjiewu/anaconda3/lib/python3.11/site-packages/ipykernel_launcher.py\", line 17, in <module>\n",
      "    app.launch_new_instance()\n",
      "  File \"/Users/jinjiewu/anaconda3/lib/python3.11/site-packages/traitlets/config/application.py\", line 992, in launch_instance\n",
      "    app.start()\n",
      "  File \"/Users/jinjiewu/anaconda3/lib/python3.11/site-packages/ipykernel/kernelapp.py\", line 736, in start\n",
      "    self.io_loop.start()\n",
      "  File \"/Users/jinjiewu/anaconda3/lib/python3.11/site-packages/tornado/platform/asyncio.py\", line 195, in start\n",
      "    self.asyncio_loop.run_forever()\n",
      "  File \"/Users/jinjiewu/anaconda3/lib/python3.11/asyncio/base_events.py\", line 607, in run_forever\n",
      "    self._run_once()\n",
      "  File \"/Users/jinjiewu/anaconda3/lib/python3.11/asyncio/base_events.py\", line 1922, in _run_once\n",
      "    handle._run()\n",
      "  File \"/Users/jinjiewu/anaconda3/lib/python3.11/asyncio/events.py\", line 80, in _run\n",
      "    self._context.run(self._callback, *self._args)\n",
      "  File \"/Users/jinjiewu/anaconda3/lib/python3.11/site-packages/ipykernel/kernelbase.py\", line 516, in dispatch_queue\n",
      "    await self.process_one()\n",
      "  File \"/Users/jinjiewu/anaconda3/lib/python3.11/site-packages/ipykernel/kernelbase.py\", line 505, in process_one\n",
      "    await dispatch(*args)\n",
      "  File \"/Users/jinjiewu/anaconda3/lib/python3.11/site-packages/ipykernel/kernelbase.py\", line 412, in dispatch_shell\n",
      "    await result\n",
      "  File \"/Users/jinjiewu/anaconda3/lib/python3.11/site-packages/ipykernel/kernelbase.py\", line 740, in execute_request\n",
      "    reply_content = await reply_content\n",
      "  File \"/Users/jinjiewu/anaconda3/lib/python3.11/site-packages/ipykernel/ipkernel.py\", line 422, in do_execute\n",
      "    res = shell.run_cell(\n",
      "  File \"/Users/jinjiewu/anaconda3/lib/python3.11/site-packages/ipykernel/zmqshell.py\", line 546, in run_cell\n",
      "    return super().run_cell(*args, **kwargs)\n",
      "  File \"/Users/jinjiewu/anaconda3/lib/python3.11/site-packages/IPython/core/interactiveshell.py\", line 3024, in run_cell\n",
      "    result = self._run_cell(\n",
      "  File \"/Users/jinjiewu/anaconda3/lib/python3.11/site-packages/IPython/core/interactiveshell.py\", line 3079, in _run_cell\n",
      "    result = runner(coro)\n",
      "  File \"/Users/jinjiewu/anaconda3/lib/python3.11/site-packages/IPython/core/async_helpers.py\", line 129, in _pseudo_sync_runner\n",
      "    coro.send(None)\n",
      "  File \"/Users/jinjiewu/anaconda3/lib/python3.11/site-packages/IPython/core/interactiveshell.py\", line 3284, in run_cell_async\n",
      "    has_raised = await self.run_ast_nodes(code_ast.body, cell_name,\n",
      "  File \"/Users/jinjiewu/anaconda3/lib/python3.11/site-packages/IPython/core/interactiveshell.py\", line 3466, in run_ast_nodes\n",
      "    if await self.run_code(code, result, async_=asy):\n",
      "  File \"/Users/jinjiewu/anaconda3/lib/python3.11/site-packages/IPython/core/interactiveshell.py\", line 3526, in run_code\n",
      "    exec(code_obj, self.user_global_ns, self.user_ns)\n",
      "  File \"/var/folders/vw/qhm4x34n2tzdd67qh3859yp80000gn/T/ipykernel_3458/2757584945.py\", line 15, in <module>\n",
      "    logger.info(f\"Skipping image_id {image_id} as response already exists.\")\n",
      "Message: 'Skipping image_id DERM_100736.jpg as response already exists.'\n",
      "Arguments: ()\n",
      "--- Logging error ---\n",
      "Traceback (most recent call last):\n",
      "  File \"/Users/jinjiewu/anaconda3/lib/python3.11/logging/__init__.py\", line 1114, in emit\n",
      "    self.flush()\n",
      "  File \"/Users/jinjiewu/anaconda3/lib/python3.11/logging/__init__.py\", line 1094, in flush\n",
      "    self.stream.flush()\n",
      "OSError: [Errno 28] No space left on device\n",
      "Call stack:\n",
      "  File \"<frozen runpy>\", line 198, in _run_module_as_main\n",
      "  File \"<frozen runpy>\", line 88, in _run_code\n",
      "  File \"/Users/jinjiewu/anaconda3/lib/python3.11/site-packages/ipykernel_launcher.py\", line 17, in <module>\n",
      "    app.launch_new_instance()\n",
      "  File \"/Users/jinjiewu/anaconda3/lib/python3.11/site-packages/traitlets/config/application.py\", line 992, in launch_instance\n",
      "    app.start()\n",
      "  File \"/Users/jinjiewu/anaconda3/lib/python3.11/site-packages/ipykernel/kernelapp.py\", line 736, in start\n",
      "    self.io_loop.start()\n",
      "  File \"/Users/jinjiewu/anaconda3/lib/python3.11/site-packages/tornado/platform/asyncio.py\", line 195, in start\n",
      "    self.asyncio_loop.run_forever()\n",
      "  File \"/Users/jinjiewu/anaconda3/lib/python3.11/asyncio/base_events.py\", line 607, in run_forever\n",
      "    self._run_once()\n",
      "  File \"/Users/jinjiewu/anaconda3/lib/python3.11/asyncio/base_events.py\", line 1922, in _run_once\n",
      "    handle._run()\n",
      "  File \"/Users/jinjiewu/anaconda3/lib/python3.11/asyncio/events.py\", line 80, in _run\n",
      "    self._context.run(self._callback, *self._args)\n",
      "  File \"/Users/jinjiewu/anaconda3/lib/python3.11/site-packages/ipykernel/kernelbase.py\", line 516, in dispatch_queue\n",
      "    await self.process_one()\n",
      "  File \"/Users/jinjiewu/anaconda3/lib/python3.11/site-packages/ipykernel/kernelbase.py\", line 505, in process_one\n",
      "    await dispatch(*args)\n",
      "  File \"/Users/jinjiewu/anaconda3/lib/python3.11/site-packages/ipykernel/kernelbase.py\", line 412, in dispatch_shell\n",
      "    await result\n",
      "  File \"/Users/jinjiewu/anaconda3/lib/python3.11/site-packages/ipykernel/kernelbase.py\", line 740, in execute_request\n",
      "    reply_content = await reply_content\n",
      "  File \"/Users/jinjiewu/anaconda3/lib/python3.11/site-packages/ipykernel/ipkernel.py\", line 422, in do_execute\n",
      "    res = shell.run_cell(\n",
      "  File \"/Users/jinjiewu/anaconda3/lib/python3.11/site-packages/ipykernel/zmqshell.py\", line 546, in run_cell\n",
      "    return super().run_cell(*args, **kwargs)\n",
      "  File \"/Users/jinjiewu/anaconda3/lib/python3.11/site-packages/IPython/core/interactiveshell.py\", line 3024, in run_cell\n",
      "    result = self._run_cell(\n",
      "  File \"/Users/jinjiewu/anaconda3/lib/python3.11/site-packages/IPython/core/interactiveshell.py\", line 3079, in _run_cell\n",
      "    result = runner(coro)\n",
      "  File \"/Users/jinjiewu/anaconda3/lib/python3.11/site-packages/IPython/core/async_helpers.py\", line 129, in _pseudo_sync_runner\n",
      "    coro.send(None)\n",
      "  File \"/Users/jinjiewu/anaconda3/lib/python3.11/site-packages/IPython/core/interactiveshell.py\", line 3284, in run_cell_async\n",
      "    has_raised = await self.run_ast_nodes(code_ast.body, cell_name,\n",
      "  File \"/Users/jinjiewu/anaconda3/lib/python3.11/site-packages/IPython/core/interactiveshell.py\", line 3466, in run_ast_nodes\n",
      "    if await self.run_code(code, result, async_=asy):\n",
      "  File \"/Users/jinjiewu/anaconda3/lib/python3.11/site-packages/IPython/core/interactiveshell.py\", line 3526, in run_code\n",
      "    exec(code_obj, self.user_global_ns, self.user_ns)\n",
      "  File \"/var/folders/vw/qhm4x34n2tzdd67qh3859yp80000gn/T/ipykernel_3458/2757584945.py\", line 19, in <module>\n",
      "    result = call_gemini_api(request)\n",
      "  File \"/var/folders/vw/qhm4x34n2tzdd67qh3859yp80000gn/T/ipykernel_3458/388332256.py\", line 15, in call_gemini_api\n",
      "    q1_general_response = api_handler.generate_from_pil_image(pil_image, q1_general)\n",
      "  File \"/Users/jinjiewu/myDermaSynth/DermaSynth/src/gemini_api.py\", line 94, in generate_from_pil_image\n",
      "    response = self.client.models.generate_content(\n",
      "  File \"/Users/jinjiewu/anaconda3/lib/python3.11/site-packages/google/genai/models.py\", line 4934, in generate_content\n",
      "    logger.info(\n",
      "Message: 'AFC is enabled with max remote calls: 10.'\n",
      "Arguments: ()\n",
      "--- Logging error ---\n",
      "Traceback (most recent call last):\n",
      "  File \"/Users/jinjiewu/anaconda3/lib/python3.11/logging/__init__.py\", line 1114, in emit\n",
      "    self.flush()\n",
      "  File \"/Users/jinjiewu/anaconda3/lib/python3.11/logging/__init__.py\", line 1094, in flush\n",
      "    self.stream.flush()\n",
      "OSError: [Errno 28] No space left on device\n",
      "Call stack:\n",
      "  File \"<frozen runpy>\", line 198, in _run_module_as_main\n",
      "  File \"<frozen runpy>\", line 88, in _run_code\n",
      "  File \"/Users/jinjiewu/anaconda3/lib/python3.11/site-packages/ipykernel_launcher.py\", line 17, in <module>\n",
      "    app.launch_new_instance()\n",
      "  File \"/Users/jinjiewu/anaconda3/lib/python3.11/site-packages/traitlets/config/application.py\", line 992, in launch_instance\n",
      "    app.start()\n",
      "  File \"/Users/jinjiewu/anaconda3/lib/python3.11/site-packages/ipykernel/kernelapp.py\", line 736, in start\n",
      "    self.io_loop.start()\n",
      "  File \"/Users/jinjiewu/anaconda3/lib/python3.11/site-packages/tornado/platform/asyncio.py\", line 195, in start\n",
      "    self.asyncio_loop.run_forever()\n",
      "  File \"/Users/jinjiewu/anaconda3/lib/python3.11/asyncio/base_events.py\", line 607, in run_forever\n",
      "    self._run_once()\n",
      "  File \"/Users/jinjiewu/anaconda3/lib/python3.11/asyncio/base_events.py\", line 1922, in _run_once\n",
      "    handle._run()\n",
      "  File \"/Users/jinjiewu/anaconda3/lib/python3.11/asyncio/events.py\", line 80, in _run\n",
      "    self._context.run(self._callback, *self._args)\n",
      "  File \"/Users/jinjiewu/anaconda3/lib/python3.11/site-packages/ipykernel/kernelbase.py\", line 516, in dispatch_queue\n",
      "    await self.process_one()\n",
      "  File \"/Users/jinjiewu/anaconda3/lib/python3.11/site-packages/ipykernel/kernelbase.py\", line 505, in process_one\n",
      "    await dispatch(*args)\n",
      "  File \"/Users/jinjiewu/anaconda3/lib/python3.11/site-packages/ipykernel/kernelbase.py\", line 412, in dispatch_shell\n",
      "    await result\n",
      "  File \"/Users/jinjiewu/anaconda3/lib/python3.11/site-packages/ipykernel/kernelbase.py\", line 740, in execute_request\n",
      "    reply_content = await reply_content\n",
      "  File \"/Users/jinjiewu/anaconda3/lib/python3.11/site-packages/ipykernel/ipkernel.py\", line 422, in do_execute\n",
      "    res = shell.run_cell(\n",
      "  File \"/Users/jinjiewu/anaconda3/lib/python3.11/site-packages/ipykernel/zmqshell.py\", line 546, in run_cell\n",
      "    return super().run_cell(*args, **kwargs)\n",
      "  File \"/Users/jinjiewu/anaconda3/lib/python3.11/site-packages/IPython/core/interactiveshell.py\", line 3024, in run_cell\n",
      "    result = self._run_cell(\n",
      "  File \"/Users/jinjiewu/anaconda3/lib/python3.11/site-packages/IPython/core/interactiveshell.py\", line 3079, in _run_cell\n",
      "    result = runner(coro)\n",
      "  File \"/Users/jinjiewu/anaconda3/lib/python3.11/site-packages/IPython/core/async_helpers.py\", line 129, in _pseudo_sync_runner\n",
      "    coro.send(None)\n",
      "  File \"/Users/jinjiewu/anaconda3/lib/python3.11/site-packages/IPython/core/interactiveshell.py\", line 3284, in run_cell_async\n",
      "    has_raised = await self.run_ast_nodes(code_ast.body, cell_name,\n",
      "  File \"/Users/jinjiewu/anaconda3/lib/python3.11/site-packages/IPython/core/interactiveshell.py\", line 3466, in run_ast_nodes\n",
      "    if await self.run_code(code, result, async_=asy):\n",
      "  File \"/Users/jinjiewu/anaconda3/lib/python3.11/site-packages/IPython/core/interactiveshell.py\", line 3526, in run_code\n",
      "    exec(code_obj, self.user_global_ns, self.user_ns)\n",
      "  File \"/var/folders/vw/qhm4x34n2tzdd67qh3859yp80000gn/T/ipykernel_3458/2757584945.py\", line 19, in <module>\n",
      "    result = call_gemini_api(request)\n",
      "  File \"/var/folders/vw/qhm4x34n2tzdd67qh3859yp80000gn/T/ipykernel_3458/388332256.py\", line 15, in call_gemini_api\n",
      "    q1_general_response = api_handler.generate_from_pil_image(pil_image, q1_general)\n",
      "  File \"/Users/jinjiewu/myDermaSynth/DermaSynth/src/gemini_api.py\", line 94, in generate_from_pil_image\n",
      "    response = self.client.models.generate_content(\n",
      "  File \"/Users/jinjiewu/anaconda3/lib/python3.11/site-packages/google/genai/models.py\", line 4942, in generate_content\n",
      "    response = self._generate_content(\n",
      "  File \"/Users/jinjiewu/anaconda3/lib/python3.11/site-packages/google/genai/models.py\", line 3915, in _generate_content\n",
      "    response_dict = self._api_client.request(\n",
      "  File \"/Users/jinjiewu/anaconda3/lib/python3.11/site-packages/google/genai/_api_client.py\", line 655, in request\n",
      "    response = self._request(http_request, stream=False)\n",
      "  File \"/Users/jinjiewu/anaconda3/lib/python3.11/site-packages/google/genai/_api_client.py\", line 577, in _request\n",
      "    response = self._httpx_client.request(\n",
      "  File \"/Users/jinjiewu/anaconda3/lib/python3.11/site-packages/httpx/_client.py\", line 825, in request\n",
      "    return self.send(request, auth=auth, follow_redirects=follow_redirects)\n",
      "  File \"/Users/jinjiewu/anaconda3/lib/python3.11/site-packages/httpx/_client.py\", line 914, in send\n",
      "    response = self._send_handling_auth(\n",
      "  File \"/Users/jinjiewu/anaconda3/lib/python3.11/site-packages/httpx/_client.py\", line 942, in _send_handling_auth\n",
      "    response = self._send_handling_redirects(\n",
      "  File \"/Users/jinjiewu/anaconda3/lib/python3.11/site-packages/httpx/_client.py\", line 979, in _send_handling_redirects\n",
      "    response = self._send_single_request(request)\n",
      "  File \"/Users/jinjiewu/anaconda3/lib/python3.11/site-packages/httpx/_client.py\", line 1025, in _send_single_request\n",
      "    logger.info(\n",
      "Message: 'HTTP Request: %s %s \"%s %d %s\"'\n",
      "Arguments: ('POST', URL('https://generativelanguage.googleapis.com/v1beta/models/gemini-2.0-flash-exp:generateContent'), 'HTTP/1.1', 200, 'OK')\n",
      "--- Logging error ---\n",
      "Traceback (most recent call last):\n",
      "  File \"/Users/jinjiewu/anaconda3/lib/python3.11/logging/__init__.py\", line 1114, in emit\n",
      "    self.flush()\n",
      "  File \"/Users/jinjiewu/anaconda3/lib/python3.11/logging/__init__.py\", line 1094, in flush\n",
      "    self.stream.flush()\n",
      "OSError: [Errno 28] No space left on device\n",
      "Call stack:\n",
      "  File \"<frozen runpy>\", line 198, in _run_module_as_main\n",
      "  File \"<frozen runpy>\", line 88, in _run_code\n",
      "  File \"/Users/jinjiewu/anaconda3/lib/python3.11/site-packages/ipykernel_launcher.py\", line 17, in <module>\n",
      "    app.launch_new_instance()\n",
      "  File \"/Users/jinjiewu/anaconda3/lib/python3.11/site-packages/traitlets/config/application.py\", line 992, in launch_instance\n",
      "    app.start()\n",
      "  File \"/Users/jinjiewu/anaconda3/lib/python3.11/site-packages/ipykernel/kernelapp.py\", line 736, in start\n",
      "    self.io_loop.start()\n",
      "  File \"/Users/jinjiewu/anaconda3/lib/python3.11/site-packages/tornado/platform/asyncio.py\", line 195, in start\n",
      "    self.asyncio_loop.run_forever()\n",
      "  File \"/Users/jinjiewu/anaconda3/lib/python3.11/asyncio/base_events.py\", line 607, in run_forever\n",
      "    self._run_once()\n",
      "  File \"/Users/jinjiewu/anaconda3/lib/python3.11/asyncio/base_events.py\", line 1922, in _run_once\n",
      "    handle._run()\n",
      "  File \"/Users/jinjiewu/anaconda3/lib/python3.11/asyncio/events.py\", line 80, in _run\n",
      "    self._context.run(self._callback, *self._args)\n",
      "  File \"/Users/jinjiewu/anaconda3/lib/python3.11/site-packages/ipykernel/kernelbase.py\", line 516, in dispatch_queue\n",
      "    await self.process_one()\n",
      "  File \"/Users/jinjiewu/anaconda3/lib/python3.11/site-packages/ipykernel/kernelbase.py\", line 505, in process_one\n",
      "    await dispatch(*args)\n",
      "  File \"/Users/jinjiewu/anaconda3/lib/python3.11/site-packages/ipykernel/kernelbase.py\", line 412, in dispatch_shell\n",
      "    await result\n",
      "  File \"/Users/jinjiewu/anaconda3/lib/python3.11/site-packages/ipykernel/kernelbase.py\", line 740, in execute_request\n",
      "    reply_content = await reply_content\n",
      "  File \"/Users/jinjiewu/anaconda3/lib/python3.11/site-packages/ipykernel/ipkernel.py\", line 422, in do_execute\n",
      "    res = shell.run_cell(\n",
      "  File \"/Users/jinjiewu/anaconda3/lib/python3.11/site-packages/ipykernel/zmqshell.py\", line 546, in run_cell\n",
      "    return super().run_cell(*args, **kwargs)\n",
      "  File \"/Users/jinjiewu/anaconda3/lib/python3.11/site-packages/IPython/core/interactiveshell.py\", line 3024, in run_cell\n",
      "    result = self._run_cell(\n",
      "  File \"/Users/jinjiewu/anaconda3/lib/python3.11/site-packages/IPython/core/interactiveshell.py\", line 3079, in _run_cell\n",
      "    result = runner(coro)\n",
      "  File \"/Users/jinjiewu/anaconda3/lib/python3.11/site-packages/IPython/core/async_helpers.py\", line 129, in _pseudo_sync_runner\n",
      "    coro.send(None)\n",
      "  File \"/Users/jinjiewu/anaconda3/lib/python3.11/site-packages/IPython/core/interactiveshell.py\", line 3284, in run_cell_async\n",
      "    has_raised = await self.run_ast_nodes(code_ast.body, cell_name,\n",
      "  File \"/Users/jinjiewu/anaconda3/lib/python3.11/site-packages/IPython/core/interactiveshell.py\", line 3466, in run_ast_nodes\n",
      "    if await self.run_code(code, result, async_=asy):\n",
      "  File \"/Users/jinjiewu/anaconda3/lib/python3.11/site-packages/IPython/core/interactiveshell.py\", line 3526, in run_code\n",
      "    exec(code_obj, self.user_global_ns, self.user_ns)\n",
      "  File \"/var/folders/vw/qhm4x34n2tzdd67qh3859yp80000gn/T/ipykernel_3458/2757584945.py\", line 19, in <module>\n",
      "    result = call_gemini_api(request)\n",
      "  File \"/var/folders/vw/qhm4x34n2tzdd67qh3859yp80000gn/T/ipykernel_3458/388332256.py\", line 15, in call_gemini_api\n",
      "    q1_general_response = api_handler.generate_from_pil_image(pil_image, q1_general)\n",
      "  File \"/Users/jinjiewu/myDermaSynth/DermaSynth/src/gemini_api.py\", line 94, in generate_from_pil_image\n",
      "    response = self.client.models.generate_content(\n",
      "  File \"/Users/jinjiewu/anaconda3/lib/python3.11/site-packages/google/genai/models.py\", line 4945, in generate_content\n",
      "    logger.info(f'AFC remote call {i} is done.')\n",
      "Message: 'AFC remote call 1 is done.'\n",
      "Arguments: ()\n",
      "--- Logging error ---\n",
      "Traceback (most recent call last):\n",
      "  File \"/Users/jinjiewu/anaconda3/lib/python3.11/logging/__init__.py\", line 1114, in emit\n",
      "    self.flush()\n",
      "  File \"/Users/jinjiewu/anaconda3/lib/python3.11/logging/__init__.py\", line 1094, in flush\n",
      "    self.stream.flush()\n",
      "OSError: [Errno 28] No space left on device\n",
      "Call stack:\n",
      "  File \"<frozen runpy>\", line 198, in _run_module_as_main\n",
      "  File \"<frozen runpy>\", line 88, in _run_code\n",
      "  File \"/Users/jinjiewu/anaconda3/lib/python3.11/site-packages/ipykernel_launcher.py\", line 17, in <module>\n",
      "    app.launch_new_instance()\n",
      "  File \"/Users/jinjiewu/anaconda3/lib/python3.11/site-packages/traitlets/config/application.py\", line 992, in launch_instance\n",
      "    app.start()\n",
      "  File \"/Users/jinjiewu/anaconda3/lib/python3.11/site-packages/ipykernel/kernelapp.py\", line 736, in start\n",
      "    self.io_loop.start()\n",
      "  File \"/Users/jinjiewu/anaconda3/lib/python3.11/site-packages/tornado/platform/asyncio.py\", line 195, in start\n",
      "    self.asyncio_loop.run_forever()\n",
      "  File \"/Users/jinjiewu/anaconda3/lib/python3.11/asyncio/base_events.py\", line 607, in run_forever\n",
      "    self._run_once()\n",
      "  File \"/Users/jinjiewu/anaconda3/lib/python3.11/asyncio/base_events.py\", line 1922, in _run_once\n",
      "    handle._run()\n",
      "  File \"/Users/jinjiewu/anaconda3/lib/python3.11/asyncio/events.py\", line 80, in _run\n",
      "    self._context.run(self._callback, *self._args)\n",
      "  File \"/Users/jinjiewu/anaconda3/lib/python3.11/site-packages/ipykernel/kernelbase.py\", line 516, in dispatch_queue\n",
      "    await self.process_one()\n",
      "  File \"/Users/jinjiewu/anaconda3/lib/python3.11/site-packages/ipykernel/kernelbase.py\", line 505, in process_one\n",
      "    await dispatch(*args)\n",
      "  File \"/Users/jinjiewu/anaconda3/lib/python3.11/site-packages/ipykernel/kernelbase.py\", line 412, in dispatch_shell\n",
      "    await result\n",
      "  File \"/Users/jinjiewu/anaconda3/lib/python3.11/site-packages/ipykernel/kernelbase.py\", line 740, in execute_request\n",
      "    reply_content = await reply_content\n",
      "  File \"/Users/jinjiewu/anaconda3/lib/python3.11/site-packages/ipykernel/ipkernel.py\", line 422, in do_execute\n",
      "    res = shell.run_cell(\n",
      "  File \"/Users/jinjiewu/anaconda3/lib/python3.11/site-packages/ipykernel/zmqshell.py\", line 546, in run_cell\n",
      "    return super().run_cell(*args, **kwargs)\n",
      "  File \"/Users/jinjiewu/anaconda3/lib/python3.11/site-packages/IPython/core/interactiveshell.py\", line 3024, in run_cell\n",
      "    result = self._run_cell(\n",
      "  File \"/Users/jinjiewu/anaconda3/lib/python3.11/site-packages/IPython/core/interactiveshell.py\", line 3079, in _run_cell\n",
      "    result = runner(coro)\n",
      "  File \"/Users/jinjiewu/anaconda3/lib/python3.11/site-packages/IPython/core/async_helpers.py\", line 129, in _pseudo_sync_runner\n",
      "    coro.send(None)\n",
      "  File \"/Users/jinjiewu/anaconda3/lib/python3.11/site-packages/IPython/core/interactiveshell.py\", line 3284, in run_cell_async\n",
      "    has_raised = await self.run_ast_nodes(code_ast.body, cell_name,\n",
      "  File \"/Users/jinjiewu/anaconda3/lib/python3.11/site-packages/IPython/core/interactiveshell.py\", line 3466, in run_ast_nodes\n",
      "    if await self.run_code(code, result, async_=asy):\n",
      "  File \"/Users/jinjiewu/anaconda3/lib/python3.11/site-packages/IPython/core/interactiveshell.py\", line 3526, in run_code\n",
      "    exec(code_obj, self.user_global_ns, self.user_ns)\n",
      "  File \"/var/folders/vw/qhm4x34n2tzdd67qh3859yp80000gn/T/ipykernel_3458/2757584945.py\", line 19, in <module>\n",
      "    result = call_gemini_api(request)\n",
      "  File \"/var/folders/vw/qhm4x34n2tzdd67qh3859yp80000gn/T/ipykernel_3458/388332256.py\", line 17, in call_gemini_api\n",
      "    q2_dataset_response = api_handler.generate_from_pil_image(pil_image, q2_dataset_specific)\n",
      "  File \"/Users/jinjiewu/myDermaSynth/DermaSynth/src/gemini_api.py\", line 94, in generate_from_pil_image\n",
      "    response = self.client.models.generate_content(\n",
      "  File \"/Users/jinjiewu/anaconda3/lib/python3.11/site-packages/google/genai/models.py\", line 4934, in generate_content\n",
      "    logger.info(\n",
      "Message: 'AFC is enabled with max remote calls: 10.'\n",
      "Arguments: ()\n",
      "--- Logging error ---\n",
      "Traceback (most recent call last):\n",
      "  File \"/Users/jinjiewu/anaconda3/lib/python3.11/logging/__init__.py\", line 1114, in emit\n",
      "    self.flush()\n",
      "  File \"/Users/jinjiewu/anaconda3/lib/python3.11/logging/__init__.py\", line 1094, in flush\n",
      "    self.stream.flush()\n",
      "OSError: [Errno 28] No space left on device\n",
      "Call stack:\n",
      "  File \"<frozen runpy>\", line 198, in _run_module_as_main\n",
      "  File \"<frozen runpy>\", line 88, in _run_code\n",
      "  File \"/Users/jinjiewu/anaconda3/lib/python3.11/site-packages/ipykernel_launcher.py\", line 17, in <module>\n",
      "    app.launch_new_instance()\n",
      "  File \"/Users/jinjiewu/anaconda3/lib/python3.11/site-packages/traitlets/config/application.py\", line 992, in launch_instance\n",
      "    app.start()\n",
      "  File \"/Users/jinjiewu/anaconda3/lib/python3.11/site-packages/ipykernel/kernelapp.py\", line 736, in start\n",
      "    self.io_loop.start()\n",
      "  File \"/Users/jinjiewu/anaconda3/lib/python3.11/site-packages/tornado/platform/asyncio.py\", line 195, in start\n",
      "    self.asyncio_loop.run_forever()\n",
      "  File \"/Users/jinjiewu/anaconda3/lib/python3.11/asyncio/base_events.py\", line 607, in run_forever\n",
      "    self._run_once()\n",
      "  File \"/Users/jinjiewu/anaconda3/lib/python3.11/asyncio/base_events.py\", line 1922, in _run_once\n",
      "    handle._run()\n",
      "  File \"/Users/jinjiewu/anaconda3/lib/python3.11/asyncio/events.py\", line 80, in _run\n",
      "    self._context.run(self._callback, *self._args)\n",
      "  File \"/Users/jinjiewu/anaconda3/lib/python3.11/site-packages/ipykernel/kernelbase.py\", line 516, in dispatch_queue\n",
      "    await self.process_one()\n",
      "  File \"/Users/jinjiewu/anaconda3/lib/python3.11/site-packages/ipykernel/kernelbase.py\", line 505, in process_one\n",
      "    await dispatch(*args)\n",
      "  File \"/Users/jinjiewu/anaconda3/lib/python3.11/site-packages/ipykernel/kernelbase.py\", line 412, in dispatch_shell\n",
      "    await result\n",
      "  File \"/Users/jinjiewu/anaconda3/lib/python3.11/site-packages/ipykernel/kernelbase.py\", line 740, in execute_request\n",
      "    reply_content = await reply_content\n",
      "  File \"/Users/jinjiewu/anaconda3/lib/python3.11/site-packages/ipykernel/ipkernel.py\", line 422, in do_execute\n",
      "    res = shell.run_cell(\n",
      "  File \"/Users/jinjiewu/anaconda3/lib/python3.11/site-packages/ipykernel/zmqshell.py\", line 546, in run_cell\n",
      "    return super().run_cell(*args, **kwargs)\n",
      "  File \"/Users/jinjiewu/anaconda3/lib/python3.11/site-packages/IPython/core/interactiveshell.py\", line 3024, in run_cell\n",
      "    result = self._run_cell(\n",
      "  File \"/Users/jinjiewu/anaconda3/lib/python3.11/site-packages/IPython/core/interactiveshell.py\", line 3079, in _run_cell\n",
      "    result = runner(coro)\n",
      "  File \"/Users/jinjiewu/anaconda3/lib/python3.11/site-packages/IPython/core/async_helpers.py\", line 129, in _pseudo_sync_runner\n",
      "    coro.send(None)\n",
      "  File \"/Users/jinjiewu/anaconda3/lib/python3.11/site-packages/IPython/core/interactiveshell.py\", line 3284, in run_cell_async\n",
      "    has_raised = await self.run_ast_nodes(code_ast.body, cell_name,\n",
      "  File \"/Users/jinjiewu/anaconda3/lib/python3.11/site-packages/IPython/core/interactiveshell.py\", line 3466, in run_ast_nodes\n",
      "    if await self.run_code(code, result, async_=asy):\n",
      "  File \"/Users/jinjiewu/anaconda3/lib/python3.11/site-packages/IPython/core/interactiveshell.py\", line 3526, in run_code\n",
      "    exec(code_obj, self.user_global_ns, self.user_ns)\n",
      "  File \"/var/folders/vw/qhm4x34n2tzdd67qh3859yp80000gn/T/ipykernel_3458/2757584945.py\", line 19, in <module>\n",
      "    result = call_gemini_api(request)\n",
      "  File \"/var/folders/vw/qhm4x34n2tzdd67qh3859yp80000gn/T/ipykernel_3458/388332256.py\", line 17, in call_gemini_api\n",
      "    q2_dataset_response = api_handler.generate_from_pil_image(pil_image, q2_dataset_specific)\n",
      "  File \"/Users/jinjiewu/myDermaSynth/DermaSynth/src/gemini_api.py\", line 94, in generate_from_pil_image\n",
      "    response = self.client.models.generate_content(\n",
      "  File \"/Users/jinjiewu/anaconda3/lib/python3.11/site-packages/google/genai/models.py\", line 4942, in generate_content\n",
      "    response = self._generate_content(\n",
      "  File \"/Users/jinjiewu/anaconda3/lib/python3.11/site-packages/google/genai/models.py\", line 3915, in _generate_content\n",
      "    response_dict = self._api_client.request(\n",
      "  File \"/Users/jinjiewu/anaconda3/lib/python3.11/site-packages/google/genai/_api_client.py\", line 655, in request\n",
      "    response = self._request(http_request, stream=False)\n",
      "  File \"/Users/jinjiewu/anaconda3/lib/python3.11/site-packages/google/genai/_api_client.py\", line 577, in _request\n",
      "    response = self._httpx_client.request(\n",
      "  File \"/Users/jinjiewu/anaconda3/lib/python3.11/site-packages/httpx/_client.py\", line 825, in request\n",
      "    return self.send(request, auth=auth, follow_redirects=follow_redirects)\n",
      "  File \"/Users/jinjiewu/anaconda3/lib/python3.11/site-packages/httpx/_client.py\", line 914, in send\n",
      "    response = self._send_handling_auth(\n",
      "  File \"/Users/jinjiewu/anaconda3/lib/python3.11/site-packages/httpx/_client.py\", line 942, in _send_handling_auth\n",
      "    response = self._send_handling_redirects(\n",
      "  File \"/Users/jinjiewu/anaconda3/lib/python3.11/site-packages/httpx/_client.py\", line 979, in _send_handling_redirects\n",
      "    response = self._send_single_request(request)\n",
      "  File \"/Users/jinjiewu/anaconda3/lib/python3.11/site-packages/httpx/_client.py\", line 1025, in _send_single_request\n",
      "    logger.info(\n",
      "Message: 'HTTP Request: %s %s \"%s %d %s\"'\n",
      "Arguments: ('POST', URL('https://generativelanguage.googleapis.com/v1beta/models/gemini-2.0-flash-exp:generateContent'), 'HTTP/1.1', 200, 'OK')\n",
      "--- Logging error ---\n",
      "Traceback (most recent call last):\n",
      "  File \"/Users/jinjiewu/anaconda3/lib/python3.11/logging/__init__.py\", line 1114, in emit\n",
      "    self.flush()\n",
      "  File \"/Users/jinjiewu/anaconda3/lib/python3.11/logging/__init__.py\", line 1094, in flush\n",
      "    self.stream.flush()\n",
      "OSError: [Errno 28] No space left on device\n",
      "Call stack:\n",
      "  File \"<frozen runpy>\", line 198, in _run_module_as_main\n",
      "  File \"<frozen runpy>\", line 88, in _run_code\n",
      "  File \"/Users/jinjiewu/anaconda3/lib/python3.11/site-packages/ipykernel_launcher.py\", line 17, in <module>\n",
      "    app.launch_new_instance()\n",
      "  File \"/Users/jinjiewu/anaconda3/lib/python3.11/site-packages/traitlets/config/application.py\", line 992, in launch_instance\n",
      "    app.start()\n",
      "  File \"/Users/jinjiewu/anaconda3/lib/python3.11/site-packages/ipykernel/kernelapp.py\", line 736, in start\n",
      "    self.io_loop.start()\n",
      "  File \"/Users/jinjiewu/anaconda3/lib/python3.11/site-packages/tornado/platform/asyncio.py\", line 195, in start\n",
      "    self.asyncio_loop.run_forever()\n",
      "  File \"/Users/jinjiewu/anaconda3/lib/python3.11/asyncio/base_events.py\", line 607, in run_forever\n",
      "    self._run_once()\n",
      "  File \"/Users/jinjiewu/anaconda3/lib/python3.11/asyncio/base_events.py\", line 1922, in _run_once\n",
      "    handle._run()\n",
      "  File \"/Users/jinjiewu/anaconda3/lib/python3.11/asyncio/events.py\", line 80, in _run\n",
      "    self._context.run(self._callback, *self._args)\n",
      "  File \"/Users/jinjiewu/anaconda3/lib/python3.11/site-packages/ipykernel/kernelbase.py\", line 516, in dispatch_queue\n",
      "    await self.process_one()\n",
      "  File \"/Users/jinjiewu/anaconda3/lib/python3.11/site-packages/ipykernel/kernelbase.py\", line 505, in process_one\n",
      "    await dispatch(*args)\n",
      "  File \"/Users/jinjiewu/anaconda3/lib/python3.11/site-packages/ipykernel/kernelbase.py\", line 412, in dispatch_shell\n",
      "    await result\n",
      "  File \"/Users/jinjiewu/anaconda3/lib/python3.11/site-packages/ipykernel/kernelbase.py\", line 740, in execute_request\n",
      "    reply_content = await reply_content\n",
      "  File \"/Users/jinjiewu/anaconda3/lib/python3.11/site-packages/ipykernel/ipkernel.py\", line 422, in do_execute\n",
      "    res = shell.run_cell(\n",
      "  File \"/Users/jinjiewu/anaconda3/lib/python3.11/site-packages/ipykernel/zmqshell.py\", line 546, in run_cell\n",
      "    return super().run_cell(*args, **kwargs)\n",
      "  File \"/Users/jinjiewu/anaconda3/lib/python3.11/site-packages/IPython/core/interactiveshell.py\", line 3024, in run_cell\n",
      "    result = self._run_cell(\n",
      "  File \"/Users/jinjiewu/anaconda3/lib/python3.11/site-packages/IPython/core/interactiveshell.py\", line 3079, in _run_cell\n",
      "    result = runner(coro)\n",
      "  File \"/Users/jinjiewu/anaconda3/lib/python3.11/site-packages/IPython/core/async_helpers.py\", line 129, in _pseudo_sync_runner\n",
      "    coro.send(None)\n",
      "  File \"/Users/jinjiewu/anaconda3/lib/python3.11/site-packages/IPython/core/interactiveshell.py\", line 3284, in run_cell_async\n",
      "    has_raised = await self.run_ast_nodes(code_ast.body, cell_name,\n",
      "  File \"/Users/jinjiewu/anaconda3/lib/python3.11/site-packages/IPython/core/interactiveshell.py\", line 3466, in run_ast_nodes\n",
      "    if await self.run_code(code, result, async_=asy):\n",
      "  File \"/Users/jinjiewu/anaconda3/lib/python3.11/site-packages/IPython/core/interactiveshell.py\", line 3526, in run_code\n",
      "    exec(code_obj, self.user_global_ns, self.user_ns)\n",
      "  File \"/var/folders/vw/qhm4x34n2tzdd67qh3859yp80000gn/T/ipykernel_3458/2757584945.py\", line 19, in <module>\n",
      "    result = call_gemini_api(request)\n",
      "  File \"/var/folders/vw/qhm4x34n2tzdd67qh3859yp80000gn/T/ipykernel_3458/388332256.py\", line 17, in call_gemini_api\n",
      "    q2_dataset_response = api_handler.generate_from_pil_image(pil_image, q2_dataset_specific)\n",
      "  File \"/Users/jinjiewu/myDermaSynth/DermaSynth/src/gemini_api.py\", line 94, in generate_from_pil_image\n",
      "    response = self.client.models.generate_content(\n",
      "  File \"/Users/jinjiewu/anaconda3/lib/python3.11/site-packages/google/genai/models.py\", line 4945, in generate_content\n",
      "    logger.info(f'AFC remote call {i} is done.')\n",
      "Message: 'AFC remote call 1 is done.'\n",
      "Arguments: ()\n",
      "--- Logging error ---\n",
      "Traceback (most recent call last):\n",
      "  File \"/var/folders/vw/qhm4x34n2tzdd67qh3859yp80000gn/T/ipykernel_3458/2757584945.py\", line 21, in <module>\n",
      "    with open(generated_response_file, \"w\") as out_file:\n",
      "         ^^^^^^^^^^^^^^^^^^^^^^^^^^^^^^^^^^\n",
      "  File \"/Users/jinjiewu/anaconda3/lib/python3.11/site-packages/IPython/core/interactiveshell.py\", line 286, in _modified_open\n",
      "    return io_open(file, *args, **kwargs)\n",
      "           ^^^^^^^^^^^^^^^^^^^^^^^^^^^^^^\n",
      "OSError: [Errno 28] No space left on device: '../api_results/derm12345/DERM_100737.jpg_response.json'\n",
      "\n",
      "During handling of the above exception, another exception occurred:\n",
      "\n",
      "Traceback (most recent call last):\n",
      "  File \"/Users/jinjiewu/anaconda3/lib/python3.11/logging/__init__.py\", line 1114, in emit\n",
      "    self.flush()\n",
      "  File \"/Users/jinjiewu/anaconda3/lib/python3.11/logging/__init__.py\", line 1094, in flush\n",
      "    self.stream.flush()\n",
      "OSError: [Errno 28] No space left on device\n",
      "Call stack:\n",
      "  File \"<frozen runpy>\", line 198, in _run_module_as_main\n",
      "  File \"<frozen runpy>\", line 88, in _run_code\n",
      "  File \"/Users/jinjiewu/anaconda3/lib/python3.11/site-packages/ipykernel_launcher.py\", line 17, in <module>\n",
      "    app.launch_new_instance()\n",
      "  File \"/Users/jinjiewu/anaconda3/lib/python3.11/site-packages/traitlets/config/application.py\", line 992, in launch_instance\n",
      "    app.start()\n",
      "  File \"/Users/jinjiewu/anaconda3/lib/python3.11/site-packages/ipykernel/kernelapp.py\", line 736, in start\n",
      "    self.io_loop.start()\n",
      "  File \"/Users/jinjiewu/anaconda3/lib/python3.11/site-packages/tornado/platform/asyncio.py\", line 195, in start\n",
      "    self.asyncio_loop.run_forever()\n",
      "  File \"/Users/jinjiewu/anaconda3/lib/python3.11/asyncio/base_events.py\", line 607, in run_forever\n",
      "    self._run_once()\n",
      "  File \"/Users/jinjiewu/anaconda3/lib/python3.11/asyncio/base_events.py\", line 1922, in _run_once\n",
      "    handle._run()\n",
      "  File \"/Users/jinjiewu/anaconda3/lib/python3.11/asyncio/events.py\", line 80, in _run\n",
      "    self._context.run(self._callback, *self._args)\n",
      "  File \"/Users/jinjiewu/anaconda3/lib/python3.11/site-packages/ipykernel/kernelbase.py\", line 516, in dispatch_queue\n",
      "    await self.process_one()\n",
      "  File \"/Users/jinjiewu/anaconda3/lib/python3.11/site-packages/ipykernel/kernelbase.py\", line 505, in process_one\n",
      "    await dispatch(*args)\n",
      "  File \"/Users/jinjiewu/anaconda3/lib/python3.11/site-packages/ipykernel/kernelbase.py\", line 412, in dispatch_shell\n",
      "    await result\n",
      "  File \"/Users/jinjiewu/anaconda3/lib/python3.11/site-packages/ipykernel/kernelbase.py\", line 740, in execute_request\n",
      "    reply_content = await reply_content\n",
      "  File \"/Users/jinjiewu/anaconda3/lib/python3.11/site-packages/ipykernel/ipkernel.py\", line 422, in do_execute\n",
      "    res = shell.run_cell(\n",
      "  File \"/Users/jinjiewu/anaconda3/lib/python3.11/site-packages/ipykernel/zmqshell.py\", line 546, in run_cell\n",
      "    return super().run_cell(*args, **kwargs)\n",
      "  File \"/Users/jinjiewu/anaconda3/lib/python3.11/site-packages/IPython/core/interactiveshell.py\", line 3024, in run_cell\n",
      "    result = self._run_cell(\n",
      "  File \"/Users/jinjiewu/anaconda3/lib/python3.11/site-packages/IPython/core/interactiveshell.py\", line 3079, in _run_cell\n",
      "    result = runner(coro)\n",
      "  File \"/Users/jinjiewu/anaconda3/lib/python3.11/site-packages/IPython/core/async_helpers.py\", line 129, in _pseudo_sync_runner\n",
      "    coro.send(None)\n",
      "  File \"/Users/jinjiewu/anaconda3/lib/python3.11/site-packages/IPython/core/interactiveshell.py\", line 3284, in run_cell_async\n",
      "    has_raised = await self.run_ast_nodes(code_ast.body, cell_name,\n",
      "  File \"/Users/jinjiewu/anaconda3/lib/python3.11/site-packages/IPython/core/interactiveshell.py\", line 3466, in run_ast_nodes\n",
      "    if await self.run_code(code, result, async_=asy):\n",
      "  File \"/Users/jinjiewu/anaconda3/lib/python3.11/site-packages/IPython/core/interactiveshell.py\", line 3526, in run_code\n",
      "    exec(code_obj, self.user_global_ns, self.user_ns)\n",
      "  File \"/var/folders/vw/qhm4x34n2tzdd67qh3859yp80000gn/T/ipykernel_3458/2757584945.py\", line 26, in <module>\n",
      "    logger.warning(f\"Error processing image_id {image_id}: {e}\")\n",
      "Message: \"Error processing image_id DERM_100737.jpg: [Errno 28] No space left on device: '../api_results/derm12345/DERM_100737.jpg_response.json'\"\n",
      "Arguments: ()\n",
      "--- Logging error ---\n",
      "Traceback (most recent call last):\n",
      "  File \"/Users/jinjiewu/anaconda3/lib/python3.11/logging/__init__.py\", line 1114, in emit\n",
      "    self.flush()\n",
      "  File \"/Users/jinjiewu/anaconda3/lib/python3.11/logging/__init__.py\", line 1094, in flush\n",
      "    self.stream.flush()\n",
      "OSError: [Errno 28] No space left on device\n",
      "Call stack:\n",
      "  File \"<frozen runpy>\", line 198, in _run_module_as_main\n",
      "  File \"<frozen runpy>\", line 88, in _run_code\n",
      "  File \"/Users/jinjiewu/anaconda3/lib/python3.11/site-packages/ipykernel_launcher.py\", line 17, in <module>\n",
      "    app.launch_new_instance()\n",
      "  File \"/Users/jinjiewu/anaconda3/lib/python3.11/site-packages/traitlets/config/application.py\", line 992, in launch_instance\n",
      "    app.start()\n",
      "  File \"/Users/jinjiewu/anaconda3/lib/python3.11/site-packages/ipykernel/kernelapp.py\", line 736, in start\n",
      "    self.io_loop.start()\n",
      "  File \"/Users/jinjiewu/anaconda3/lib/python3.11/site-packages/tornado/platform/asyncio.py\", line 195, in start\n",
      "    self.asyncio_loop.run_forever()\n",
      "  File \"/Users/jinjiewu/anaconda3/lib/python3.11/asyncio/base_events.py\", line 607, in run_forever\n",
      "    self._run_once()\n",
      "  File \"/Users/jinjiewu/anaconda3/lib/python3.11/asyncio/base_events.py\", line 1922, in _run_once\n",
      "    handle._run()\n",
      "  File \"/Users/jinjiewu/anaconda3/lib/python3.11/asyncio/events.py\", line 80, in _run\n",
      "    self._context.run(self._callback, *self._args)\n",
      "  File \"/Users/jinjiewu/anaconda3/lib/python3.11/site-packages/ipykernel/kernelbase.py\", line 516, in dispatch_queue\n",
      "    await self.process_one()\n",
      "  File \"/Users/jinjiewu/anaconda3/lib/python3.11/site-packages/ipykernel/kernelbase.py\", line 505, in process_one\n",
      "    await dispatch(*args)\n",
      "  File \"/Users/jinjiewu/anaconda3/lib/python3.11/site-packages/ipykernel/kernelbase.py\", line 412, in dispatch_shell\n",
      "    await result\n",
      "  File \"/Users/jinjiewu/anaconda3/lib/python3.11/site-packages/ipykernel/kernelbase.py\", line 740, in execute_request\n",
      "    reply_content = await reply_content\n",
      "  File \"/Users/jinjiewu/anaconda3/lib/python3.11/site-packages/ipykernel/ipkernel.py\", line 422, in do_execute\n",
      "    res = shell.run_cell(\n",
      "  File \"/Users/jinjiewu/anaconda3/lib/python3.11/site-packages/ipykernel/zmqshell.py\", line 546, in run_cell\n",
      "    return super().run_cell(*args, **kwargs)\n",
      "  File \"/Users/jinjiewu/anaconda3/lib/python3.11/site-packages/IPython/core/interactiveshell.py\", line 3024, in run_cell\n",
      "    result = self._run_cell(\n",
      "  File \"/Users/jinjiewu/anaconda3/lib/python3.11/site-packages/IPython/core/interactiveshell.py\", line 3079, in _run_cell\n",
      "    result = runner(coro)\n",
      "  File \"/Users/jinjiewu/anaconda3/lib/python3.11/site-packages/IPython/core/async_helpers.py\", line 129, in _pseudo_sync_runner\n",
      "    coro.send(None)\n",
      "  File \"/Users/jinjiewu/anaconda3/lib/python3.11/site-packages/IPython/core/interactiveshell.py\", line 3284, in run_cell_async\n",
      "    has_raised = await self.run_ast_nodes(code_ast.body, cell_name,\n",
      "  File \"/Users/jinjiewu/anaconda3/lib/python3.11/site-packages/IPython/core/interactiveshell.py\", line 3466, in run_ast_nodes\n",
      "    if await self.run_code(code, result, async_=asy):\n",
      "  File \"/Users/jinjiewu/anaconda3/lib/python3.11/site-packages/IPython/core/interactiveshell.py\", line 3526, in run_code\n",
      "    exec(code_obj, self.user_global_ns, self.user_ns)\n",
      "  File \"/var/folders/vw/qhm4x34n2tzdd67qh3859yp80000gn/T/ipykernel_3458/2757584945.py\", line 19, in <module>\n",
      "    result = call_gemini_api(request)\n",
      "  File \"/var/folders/vw/qhm4x34n2tzdd67qh3859yp80000gn/T/ipykernel_3458/388332256.py\", line 15, in call_gemini_api\n",
      "    q1_general_response = api_handler.generate_from_pil_image(pil_image, q1_general)\n",
      "  File \"/Users/jinjiewu/myDermaSynth/DermaSynth/src/gemini_api.py\", line 94, in generate_from_pil_image\n",
      "    response = self.client.models.generate_content(\n",
      "  File \"/Users/jinjiewu/anaconda3/lib/python3.11/site-packages/google/genai/models.py\", line 4934, in generate_content\n",
      "    logger.info(\n",
      "Message: 'AFC is enabled with max remote calls: 10.'\n",
      "Arguments: ()\n",
      "--- Logging error ---\n",
      "Traceback (most recent call last):\n",
      "  File \"/Users/jinjiewu/anaconda3/lib/python3.11/logging/__init__.py\", line 1114, in emit\n",
      "    self.flush()\n",
      "  File \"/Users/jinjiewu/anaconda3/lib/python3.11/logging/__init__.py\", line 1094, in flush\n",
      "    self.stream.flush()\n",
      "OSError: [Errno 28] No space left on device\n",
      "Call stack:\n",
      "  File \"<frozen runpy>\", line 198, in _run_module_as_main\n",
      "  File \"<frozen runpy>\", line 88, in _run_code\n",
      "  File \"/Users/jinjiewu/anaconda3/lib/python3.11/site-packages/ipykernel_launcher.py\", line 17, in <module>\n",
      "    app.launch_new_instance()\n",
      "  File \"/Users/jinjiewu/anaconda3/lib/python3.11/site-packages/traitlets/config/application.py\", line 992, in launch_instance\n",
      "    app.start()\n",
      "  File \"/Users/jinjiewu/anaconda3/lib/python3.11/site-packages/ipykernel/kernelapp.py\", line 736, in start\n",
      "    self.io_loop.start()\n",
      "  File \"/Users/jinjiewu/anaconda3/lib/python3.11/site-packages/tornado/platform/asyncio.py\", line 195, in start\n",
      "    self.asyncio_loop.run_forever()\n",
      "  File \"/Users/jinjiewu/anaconda3/lib/python3.11/asyncio/base_events.py\", line 607, in run_forever\n",
      "    self._run_once()\n",
      "  File \"/Users/jinjiewu/anaconda3/lib/python3.11/asyncio/base_events.py\", line 1922, in _run_once\n",
      "    handle._run()\n",
      "  File \"/Users/jinjiewu/anaconda3/lib/python3.11/asyncio/events.py\", line 80, in _run\n",
      "    self._context.run(self._callback, *self._args)\n",
      "  File \"/Users/jinjiewu/anaconda3/lib/python3.11/site-packages/ipykernel/kernelbase.py\", line 516, in dispatch_queue\n",
      "    await self.process_one()\n",
      "  File \"/Users/jinjiewu/anaconda3/lib/python3.11/site-packages/ipykernel/kernelbase.py\", line 505, in process_one\n",
      "    await dispatch(*args)\n",
      "  File \"/Users/jinjiewu/anaconda3/lib/python3.11/site-packages/ipykernel/kernelbase.py\", line 412, in dispatch_shell\n",
      "    await result\n",
      "  File \"/Users/jinjiewu/anaconda3/lib/python3.11/site-packages/ipykernel/kernelbase.py\", line 740, in execute_request\n",
      "    reply_content = await reply_content\n",
      "  File \"/Users/jinjiewu/anaconda3/lib/python3.11/site-packages/ipykernel/ipkernel.py\", line 422, in do_execute\n",
      "    res = shell.run_cell(\n",
      "  File \"/Users/jinjiewu/anaconda3/lib/python3.11/site-packages/ipykernel/zmqshell.py\", line 546, in run_cell\n",
      "    return super().run_cell(*args, **kwargs)\n",
      "  File \"/Users/jinjiewu/anaconda3/lib/python3.11/site-packages/IPython/core/interactiveshell.py\", line 3024, in run_cell\n",
      "    result = self._run_cell(\n",
      "  File \"/Users/jinjiewu/anaconda3/lib/python3.11/site-packages/IPython/core/interactiveshell.py\", line 3079, in _run_cell\n",
      "    result = runner(coro)\n",
      "  File \"/Users/jinjiewu/anaconda3/lib/python3.11/site-packages/IPython/core/async_helpers.py\", line 129, in _pseudo_sync_runner\n",
      "    coro.send(None)\n",
      "  File \"/Users/jinjiewu/anaconda3/lib/python3.11/site-packages/IPython/core/interactiveshell.py\", line 3284, in run_cell_async\n",
      "    has_raised = await self.run_ast_nodes(code_ast.body, cell_name,\n",
      "  File \"/Users/jinjiewu/anaconda3/lib/python3.11/site-packages/IPython/core/interactiveshell.py\", line 3466, in run_ast_nodes\n",
      "    if await self.run_code(code, result, async_=asy):\n",
      "  File \"/Users/jinjiewu/anaconda3/lib/python3.11/site-packages/IPython/core/interactiveshell.py\", line 3526, in run_code\n",
      "    exec(code_obj, self.user_global_ns, self.user_ns)\n",
      "  File \"/var/folders/vw/qhm4x34n2tzdd67qh3859yp80000gn/T/ipykernel_3458/2757584945.py\", line 19, in <module>\n",
      "    result = call_gemini_api(request)\n",
      "  File \"/var/folders/vw/qhm4x34n2tzdd67qh3859yp80000gn/T/ipykernel_3458/388332256.py\", line 15, in call_gemini_api\n",
      "    q1_general_response = api_handler.generate_from_pil_image(pil_image, q1_general)\n",
      "  File \"/Users/jinjiewu/myDermaSynth/DermaSynth/src/gemini_api.py\", line 94, in generate_from_pil_image\n",
      "    response = self.client.models.generate_content(\n",
      "  File \"/Users/jinjiewu/anaconda3/lib/python3.11/site-packages/google/genai/models.py\", line 4942, in generate_content\n",
      "    response = self._generate_content(\n",
      "  File \"/Users/jinjiewu/anaconda3/lib/python3.11/site-packages/google/genai/models.py\", line 3915, in _generate_content\n",
      "    response_dict = self._api_client.request(\n",
      "  File \"/Users/jinjiewu/anaconda3/lib/python3.11/site-packages/google/genai/_api_client.py\", line 655, in request\n",
      "    response = self._request(http_request, stream=False)\n",
      "  File \"/Users/jinjiewu/anaconda3/lib/python3.11/site-packages/google/genai/_api_client.py\", line 577, in _request\n",
      "    response = self._httpx_client.request(\n",
      "  File \"/Users/jinjiewu/anaconda3/lib/python3.11/site-packages/httpx/_client.py\", line 825, in request\n",
      "    return self.send(request, auth=auth, follow_redirects=follow_redirects)\n",
      "  File \"/Users/jinjiewu/anaconda3/lib/python3.11/site-packages/httpx/_client.py\", line 914, in send\n",
      "    response = self._send_handling_auth(\n",
      "  File \"/Users/jinjiewu/anaconda3/lib/python3.11/site-packages/httpx/_client.py\", line 942, in _send_handling_auth\n",
      "    response = self._send_handling_redirects(\n",
      "  File \"/Users/jinjiewu/anaconda3/lib/python3.11/site-packages/httpx/_client.py\", line 979, in _send_handling_redirects\n",
      "    response = self._send_single_request(request)\n",
      "  File \"/Users/jinjiewu/anaconda3/lib/python3.11/site-packages/httpx/_client.py\", line 1025, in _send_single_request\n",
      "    logger.info(\n",
      "Message: 'HTTP Request: %s %s \"%s %d %s\"'\n",
      "Arguments: ('POST', URL('https://generativelanguage.googleapis.com/v1beta/models/gemini-2.0-flash-exp:generateContent'), 'HTTP/1.1', 200, 'OK')\n",
      "--- Logging error ---\n",
      "Traceback (most recent call last):\n",
      "  File \"/Users/jinjiewu/anaconda3/lib/python3.11/logging/__init__.py\", line 1114, in emit\n",
      "    self.flush()\n",
      "  File \"/Users/jinjiewu/anaconda3/lib/python3.11/logging/__init__.py\", line 1094, in flush\n",
      "    self.stream.flush()\n",
      "OSError: [Errno 28] No space left on device\n",
      "Call stack:\n",
      "  File \"<frozen runpy>\", line 198, in _run_module_as_main\n",
      "  File \"<frozen runpy>\", line 88, in _run_code\n",
      "  File \"/Users/jinjiewu/anaconda3/lib/python3.11/site-packages/ipykernel_launcher.py\", line 17, in <module>\n",
      "    app.launch_new_instance()\n",
      "  File \"/Users/jinjiewu/anaconda3/lib/python3.11/site-packages/traitlets/config/application.py\", line 992, in launch_instance\n",
      "    app.start()\n",
      "  File \"/Users/jinjiewu/anaconda3/lib/python3.11/site-packages/ipykernel/kernelapp.py\", line 736, in start\n",
      "    self.io_loop.start()\n",
      "  File \"/Users/jinjiewu/anaconda3/lib/python3.11/site-packages/tornado/platform/asyncio.py\", line 195, in start\n",
      "    self.asyncio_loop.run_forever()\n",
      "  File \"/Users/jinjiewu/anaconda3/lib/python3.11/asyncio/base_events.py\", line 607, in run_forever\n",
      "    self._run_once()\n",
      "  File \"/Users/jinjiewu/anaconda3/lib/python3.11/asyncio/base_events.py\", line 1922, in _run_once\n",
      "    handle._run()\n",
      "  File \"/Users/jinjiewu/anaconda3/lib/python3.11/asyncio/events.py\", line 80, in _run\n",
      "    self._context.run(self._callback, *self._args)\n",
      "  File \"/Users/jinjiewu/anaconda3/lib/python3.11/site-packages/ipykernel/kernelbase.py\", line 516, in dispatch_queue\n",
      "    await self.process_one()\n",
      "  File \"/Users/jinjiewu/anaconda3/lib/python3.11/site-packages/ipykernel/kernelbase.py\", line 505, in process_one\n",
      "    await dispatch(*args)\n",
      "  File \"/Users/jinjiewu/anaconda3/lib/python3.11/site-packages/ipykernel/kernelbase.py\", line 412, in dispatch_shell\n",
      "    await result\n",
      "  File \"/Users/jinjiewu/anaconda3/lib/python3.11/site-packages/ipykernel/kernelbase.py\", line 740, in execute_request\n",
      "    reply_content = await reply_content\n",
      "  File \"/Users/jinjiewu/anaconda3/lib/python3.11/site-packages/ipykernel/ipkernel.py\", line 422, in do_execute\n",
      "    res = shell.run_cell(\n",
      "  File \"/Users/jinjiewu/anaconda3/lib/python3.11/site-packages/ipykernel/zmqshell.py\", line 546, in run_cell\n",
      "    return super().run_cell(*args, **kwargs)\n",
      "  File \"/Users/jinjiewu/anaconda3/lib/python3.11/site-packages/IPython/core/interactiveshell.py\", line 3024, in run_cell\n",
      "    result = self._run_cell(\n",
      "  File \"/Users/jinjiewu/anaconda3/lib/python3.11/site-packages/IPython/core/interactiveshell.py\", line 3079, in _run_cell\n",
      "    result = runner(coro)\n",
      "  File \"/Users/jinjiewu/anaconda3/lib/python3.11/site-packages/IPython/core/async_helpers.py\", line 129, in _pseudo_sync_runner\n",
      "    coro.send(None)\n",
      "  File \"/Users/jinjiewu/anaconda3/lib/python3.11/site-packages/IPython/core/interactiveshell.py\", line 3284, in run_cell_async\n",
      "    has_raised = await self.run_ast_nodes(code_ast.body, cell_name,\n",
      "  File \"/Users/jinjiewu/anaconda3/lib/python3.11/site-packages/IPython/core/interactiveshell.py\", line 3466, in run_ast_nodes\n",
      "    if await self.run_code(code, result, async_=asy):\n",
      "  File \"/Users/jinjiewu/anaconda3/lib/python3.11/site-packages/IPython/core/interactiveshell.py\", line 3526, in run_code\n",
      "    exec(code_obj, self.user_global_ns, self.user_ns)\n",
      "  File \"/var/folders/vw/qhm4x34n2tzdd67qh3859yp80000gn/T/ipykernel_3458/2757584945.py\", line 19, in <module>\n",
      "    result = call_gemini_api(request)\n",
      "  File \"/var/folders/vw/qhm4x34n2tzdd67qh3859yp80000gn/T/ipykernel_3458/388332256.py\", line 15, in call_gemini_api\n",
      "    q1_general_response = api_handler.generate_from_pil_image(pil_image, q1_general)\n",
      "  File \"/Users/jinjiewu/myDermaSynth/DermaSynth/src/gemini_api.py\", line 94, in generate_from_pil_image\n",
      "    response = self.client.models.generate_content(\n",
      "  File \"/Users/jinjiewu/anaconda3/lib/python3.11/site-packages/google/genai/models.py\", line 4945, in generate_content\n",
      "    logger.info(f'AFC remote call {i} is done.')\n",
      "Message: 'AFC remote call 1 is done.'\n",
      "Arguments: ()\n",
      "--- Logging error ---\n",
      "Traceback (most recent call last):\n",
      "  File \"/Users/jinjiewu/anaconda3/lib/python3.11/logging/__init__.py\", line 1114, in emit\n",
      "    self.flush()\n",
      "  File \"/Users/jinjiewu/anaconda3/lib/python3.11/logging/__init__.py\", line 1094, in flush\n",
      "    self.stream.flush()\n",
      "OSError: [Errno 28] No space left on device\n",
      "Call stack:\n",
      "  File \"<frozen runpy>\", line 198, in _run_module_as_main\n",
      "  File \"<frozen runpy>\", line 88, in _run_code\n",
      "  File \"/Users/jinjiewu/anaconda3/lib/python3.11/site-packages/ipykernel_launcher.py\", line 17, in <module>\n",
      "    app.launch_new_instance()\n",
      "  File \"/Users/jinjiewu/anaconda3/lib/python3.11/site-packages/traitlets/config/application.py\", line 992, in launch_instance\n",
      "    app.start()\n",
      "  File \"/Users/jinjiewu/anaconda3/lib/python3.11/site-packages/ipykernel/kernelapp.py\", line 736, in start\n",
      "    self.io_loop.start()\n",
      "  File \"/Users/jinjiewu/anaconda3/lib/python3.11/site-packages/tornado/platform/asyncio.py\", line 195, in start\n",
      "    self.asyncio_loop.run_forever()\n",
      "  File \"/Users/jinjiewu/anaconda3/lib/python3.11/asyncio/base_events.py\", line 607, in run_forever\n",
      "    self._run_once()\n",
      "  File \"/Users/jinjiewu/anaconda3/lib/python3.11/asyncio/base_events.py\", line 1922, in _run_once\n",
      "    handle._run()\n",
      "  File \"/Users/jinjiewu/anaconda3/lib/python3.11/asyncio/events.py\", line 80, in _run\n",
      "    self._context.run(self._callback, *self._args)\n",
      "  File \"/Users/jinjiewu/anaconda3/lib/python3.11/site-packages/ipykernel/kernelbase.py\", line 516, in dispatch_queue\n",
      "    await self.process_one()\n",
      "  File \"/Users/jinjiewu/anaconda3/lib/python3.11/site-packages/ipykernel/kernelbase.py\", line 505, in process_one\n",
      "    await dispatch(*args)\n",
      "  File \"/Users/jinjiewu/anaconda3/lib/python3.11/site-packages/ipykernel/kernelbase.py\", line 412, in dispatch_shell\n",
      "    await result\n",
      "  File \"/Users/jinjiewu/anaconda3/lib/python3.11/site-packages/ipykernel/kernelbase.py\", line 740, in execute_request\n",
      "    reply_content = await reply_content\n",
      "  File \"/Users/jinjiewu/anaconda3/lib/python3.11/site-packages/ipykernel/ipkernel.py\", line 422, in do_execute\n",
      "    res = shell.run_cell(\n",
      "  File \"/Users/jinjiewu/anaconda3/lib/python3.11/site-packages/ipykernel/zmqshell.py\", line 546, in run_cell\n",
      "    return super().run_cell(*args, **kwargs)\n",
      "  File \"/Users/jinjiewu/anaconda3/lib/python3.11/site-packages/IPython/core/interactiveshell.py\", line 3024, in run_cell\n",
      "    result = self._run_cell(\n",
      "  File \"/Users/jinjiewu/anaconda3/lib/python3.11/site-packages/IPython/core/interactiveshell.py\", line 3079, in _run_cell\n",
      "    result = runner(coro)\n",
      "  File \"/Users/jinjiewu/anaconda3/lib/python3.11/site-packages/IPython/core/async_helpers.py\", line 129, in _pseudo_sync_runner\n",
      "    coro.send(None)\n",
      "  File \"/Users/jinjiewu/anaconda3/lib/python3.11/site-packages/IPython/core/interactiveshell.py\", line 3284, in run_cell_async\n",
      "    has_raised = await self.run_ast_nodes(code_ast.body, cell_name,\n",
      "  File \"/Users/jinjiewu/anaconda3/lib/python3.11/site-packages/IPython/core/interactiveshell.py\", line 3466, in run_ast_nodes\n",
      "    if await self.run_code(code, result, async_=asy):\n",
      "  File \"/Users/jinjiewu/anaconda3/lib/python3.11/site-packages/IPython/core/interactiveshell.py\", line 3526, in run_code\n",
      "    exec(code_obj, self.user_global_ns, self.user_ns)\n",
      "  File \"/var/folders/vw/qhm4x34n2tzdd67qh3859yp80000gn/T/ipykernel_3458/2757584945.py\", line 19, in <module>\n",
      "    result = call_gemini_api(request)\n",
      "  File \"/var/folders/vw/qhm4x34n2tzdd67qh3859yp80000gn/T/ipykernel_3458/388332256.py\", line 17, in call_gemini_api\n",
      "    q2_dataset_response = api_handler.generate_from_pil_image(pil_image, q2_dataset_specific)\n",
      "  File \"/Users/jinjiewu/myDermaSynth/DermaSynth/src/gemini_api.py\", line 94, in generate_from_pil_image\n",
      "    response = self.client.models.generate_content(\n",
      "  File \"/Users/jinjiewu/anaconda3/lib/python3.11/site-packages/google/genai/models.py\", line 4934, in generate_content\n",
      "    logger.info(\n",
      "Message: 'AFC is enabled with max remote calls: 10.'\n",
      "Arguments: ()\n",
      "--- Logging error ---\n",
      "Traceback (most recent call last):\n",
      "  File \"/Users/jinjiewu/anaconda3/lib/python3.11/logging/__init__.py\", line 1114, in emit\n",
      "    self.flush()\n",
      "  File \"/Users/jinjiewu/anaconda3/lib/python3.11/logging/__init__.py\", line 1094, in flush\n",
      "    self.stream.flush()\n",
      "OSError: [Errno 28] No space left on device\n",
      "Call stack:\n",
      "  File \"<frozen runpy>\", line 198, in _run_module_as_main\n",
      "  File \"<frozen runpy>\", line 88, in _run_code\n",
      "  File \"/Users/jinjiewu/anaconda3/lib/python3.11/site-packages/ipykernel_launcher.py\", line 17, in <module>\n",
      "    app.launch_new_instance()\n",
      "  File \"/Users/jinjiewu/anaconda3/lib/python3.11/site-packages/traitlets/config/application.py\", line 992, in launch_instance\n",
      "    app.start()\n",
      "  File \"/Users/jinjiewu/anaconda3/lib/python3.11/site-packages/ipykernel/kernelapp.py\", line 736, in start\n",
      "    self.io_loop.start()\n",
      "  File \"/Users/jinjiewu/anaconda3/lib/python3.11/site-packages/tornado/platform/asyncio.py\", line 195, in start\n",
      "    self.asyncio_loop.run_forever()\n",
      "  File \"/Users/jinjiewu/anaconda3/lib/python3.11/asyncio/base_events.py\", line 607, in run_forever\n",
      "    self._run_once()\n",
      "  File \"/Users/jinjiewu/anaconda3/lib/python3.11/asyncio/base_events.py\", line 1922, in _run_once\n",
      "    handle._run()\n",
      "  File \"/Users/jinjiewu/anaconda3/lib/python3.11/asyncio/events.py\", line 80, in _run\n",
      "    self._context.run(self._callback, *self._args)\n",
      "  File \"/Users/jinjiewu/anaconda3/lib/python3.11/site-packages/ipykernel/kernelbase.py\", line 516, in dispatch_queue\n",
      "    await self.process_one()\n",
      "  File \"/Users/jinjiewu/anaconda3/lib/python3.11/site-packages/ipykernel/kernelbase.py\", line 505, in process_one\n",
      "    await dispatch(*args)\n",
      "  File \"/Users/jinjiewu/anaconda3/lib/python3.11/site-packages/ipykernel/kernelbase.py\", line 412, in dispatch_shell\n",
      "    await result\n",
      "  File \"/Users/jinjiewu/anaconda3/lib/python3.11/site-packages/ipykernel/kernelbase.py\", line 740, in execute_request\n",
      "    reply_content = await reply_content\n",
      "  File \"/Users/jinjiewu/anaconda3/lib/python3.11/site-packages/ipykernel/ipkernel.py\", line 422, in do_execute\n",
      "    res = shell.run_cell(\n",
      "  File \"/Users/jinjiewu/anaconda3/lib/python3.11/site-packages/ipykernel/zmqshell.py\", line 546, in run_cell\n",
      "    return super().run_cell(*args, **kwargs)\n",
      "  File \"/Users/jinjiewu/anaconda3/lib/python3.11/site-packages/IPython/core/interactiveshell.py\", line 3024, in run_cell\n",
      "    result = self._run_cell(\n",
      "  File \"/Users/jinjiewu/anaconda3/lib/python3.11/site-packages/IPython/core/interactiveshell.py\", line 3079, in _run_cell\n",
      "    result = runner(coro)\n",
      "  File \"/Users/jinjiewu/anaconda3/lib/python3.11/site-packages/IPython/core/async_helpers.py\", line 129, in _pseudo_sync_runner\n",
      "    coro.send(None)\n",
      "  File \"/Users/jinjiewu/anaconda3/lib/python3.11/site-packages/IPython/core/interactiveshell.py\", line 3284, in run_cell_async\n",
      "    has_raised = await self.run_ast_nodes(code_ast.body, cell_name,\n",
      "  File \"/Users/jinjiewu/anaconda3/lib/python3.11/site-packages/IPython/core/interactiveshell.py\", line 3466, in run_ast_nodes\n",
      "    if await self.run_code(code, result, async_=asy):\n",
      "  File \"/Users/jinjiewu/anaconda3/lib/python3.11/site-packages/IPython/core/interactiveshell.py\", line 3526, in run_code\n",
      "    exec(code_obj, self.user_global_ns, self.user_ns)\n",
      "  File \"/var/folders/vw/qhm4x34n2tzdd67qh3859yp80000gn/T/ipykernel_3458/2757584945.py\", line 19, in <module>\n",
      "    result = call_gemini_api(request)\n",
      "  File \"/var/folders/vw/qhm4x34n2tzdd67qh3859yp80000gn/T/ipykernel_3458/388332256.py\", line 17, in call_gemini_api\n",
      "    q2_dataset_response = api_handler.generate_from_pil_image(pil_image, q2_dataset_specific)\n",
      "  File \"/Users/jinjiewu/myDermaSynth/DermaSynth/src/gemini_api.py\", line 94, in generate_from_pil_image\n",
      "    response = self.client.models.generate_content(\n",
      "  File \"/Users/jinjiewu/anaconda3/lib/python3.11/site-packages/google/genai/models.py\", line 4942, in generate_content\n",
      "    response = self._generate_content(\n",
      "  File \"/Users/jinjiewu/anaconda3/lib/python3.11/site-packages/google/genai/models.py\", line 3915, in _generate_content\n",
      "    response_dict = self._api_client.request(\n",
      "  File \"/Users/jinjiewu/anaconda3/lib/python3.11/site-packages/google/genai/_api_client.py\", line 655, in request\n",
      "    response = self._request(http_request, stream=False)\n",
      "  File \"/Users/jinjiewu/anaconda3/lib/python3.11/site-packages/google/genai/_api_client.py\", line 577, in _request\n",
      "    response = self._httpx_client.request(\n",
      "  File \"/Users/jinjiewu/anaconda3/lib/python3.11/site-packages/httpx/_client.py\", line 825, in request\n",
      "    return self.send(request, auth=auth, follow_redirects=follow_redirects)\n",
      "  File \"/Users/jinjiewu/anaconda3/lib/python3.11/site-packages/httpx/_client.py\", line 914, in send\n",
      "    response = self._send_handling_auth(\n",
      "  File \"/Users/jinjiewu/anaconda3/lib/python3.11/site-packages/httpx/_client.py\", line 942, in _send_handling_auth\n",
      "    response = self._send_handling_redirects(\n",
      "  File \"/Users/jinjiewu/anaconda3/lib/python3.11/site-packages/httpx/_client.py\", line 979, in _send_handling_redirects\n",
      "    response = self._send_single_request(request)\n",
      "  File \"/Users/jinjiewu/anaconda3/lib/python3.11/site-packages/httpx/_client.py\", line 1025, in _send_single_request\n",
      "    logger.info(\n",
      "Message: 'HTTP Request: %s %s \"%s %d %s\"'\n",
      "Arguments: ('POST', URL('https://generativelanguage.googleapis.com/v1beta/models/gemini-2.0-flash-exp:generateContent'), 'HTTP/1.1', 200, 'OK')\n",
      "--- Logging error ---\n",
      "Traceback (most recent call last):\n",
      "  File \"/Users/jinjiewu/anaconda3/lib/python3.11/logging/__init__.py\", line 1114, in emit\n",
      "    self.flush()\n",
      "  File \"/Users/jinjiewu/anaconda3/lib/python3.11/logging/__init__.py\", line 1094, in flush\n",
      "    self.stream.flush()\n",
      "OSError: [Errno 28] No space left on device\n",
      "Call stack:\n",
      "  File \"<frozen runpy>\", line 198, in _run_module_as_main\n",
      "  File \"<frozen runpy>\", line 88, in _run_code\n",
      "  File \"/Users/jinjiewu/anaconda3/lib/python3.11/site-packages/ipykernel_launcher.py\", line 17, in <module>\n",
      "    app.launch_new_instance()\n",
      "  File \"/Users/jinjiewu/anaconda3/lib/python3.11/site-packages/traitlets/config/application.py\", line 992, in launch_instance\n",
      "    app.start()\n",
      "  File \"/Users/jinjiewu/anaconda3/lib/python3.11/site-packages/ipykernel/kernelapp.py\", line 736, in start\n",
      "    self.io_loop.start()\n",
      "  File \"/Users/jinjiewu/anaconda3/lib/python3.11/site-packages/tornado/platform/asyncio.py\", line 195, in start\n",
      "    self.asyncio_loop.run_forever()\n",
      "  File \"/Users/jinjiewu/anaconda3/lib/python3.11/asyncio/base_events.py\", line 607, in run_forever\n",
      "    self._run_once()\n",
      "  File \"/Users/jinjiewu/anaconda3/lib/python3.11/asyncio/base_events.py\", line 1922, in _run_once\n",
      "    handle._run()\n",
      "  File \"/Users/jinjiewu/anaconda3/lib/python3.11/asyncio/events.py\", line 80, in _run\n",
      "    self._context.run(self._callback, *self._args)\n",
      "  File \"/Users/jinjiewu/anaconda3/lib/python3.11/site-packages/ipykernel/kernelbase.py\", line 516, in dispatch_queue\n",
      "    await self.process_one()\n",
      "  File \"/Users/jinjiewu/anaconda3/lib/python3.11/site-packages/ipykernel/kernelbase.py\", line 505, in process_one\n",
      "    await dispatch(*args)\n",
      "  File \"/Users/jinjiewu/anaconda3/lib/python3.11/site-packages/ipykernel/kernelbase.py\", line 412, in dispatch_shell\n",
      "    await result\n",
      "  File \"/Users/jinjiewu/anaconda3/lib/python3.11/site-packages/ipykernel/kernelbase.py\", line 740, in execute_request\n",
      "    reply_content = await reply_content\n",
      "  File \"/Users/jinjiewu/anaconda3/lib/python3.11/site-packages/ipykernel/ipkernel.py\", line 422, in do_execute\n",
      "    res = shell.run_cell(\n",
      "  File \"/Users/jinjiewu/anaconda3/lib/python3.11/site-packages/ipykernel/zmqshell.py\", line 546, in run_cell\n",
      "    return super().run_cell(*args, **kwargs)\n",
      "  File \"/Users/jinjiewu/anaconda3/lib/python3.11/site-packages/IPython/core/interactiveshell.py\", line 3024, in run_cell\n",
      "    result = self._run_cell(\n",
      "  File \"/Users/jinjiewu/anaconda3/lib/python3.11/site-packages/IPython/core/interactiveshell.py\", line 3079, in _run_cell\n",
      "    result = runner(coro)\n",
      "  File \"/Users/jinjiewu/anaconda3/lib/python3.11/site-packages/IPython/core/async_helpers.py\", line 129, in _pseudo_sync_runner\n",
      "    coro.send(None)\n",
      "  File \"/Users/jinjiewu/anaconda3/lib/python3.11/site-packages/IPython/core/interactiveshell.py\", line 3284, in run_cell_async\n",
      "    has_raised = await self.run_ast_nodes(code_ast.body, cell_name,\n",
      "  File \"/Users/jinjiewu/anaconda3/lib/python3.11/site-packages/IPython/core/interactiveshell.py\", line 3466, in run_ast_nodes\n",
      "    if await self.run_code(code, result, async_=asy):\n",
      "  File \"/Users/jinjiewu/anaconda3/lib/python3.11/site-packages/IPython/core/interactiveshell.py\", line 3526, in run_code\n",
      "    exec(code_obj, self.user_global_ns, self.user_ns)\n",
      "  File \"/var/folders/vw/qhm4x34n2tzdd67qh3859yp80000gn/T/ipykernel_3458/2757584945.py\", line 19, in <module>\n",
      "    result = call_gemini_api(request)\n",
      "  File \"/var/folders/vw/qhm4x34n2tzdd67qh3859yp80000gn/T/ipykernel_3458/388332256.py\", line 17, in call_gemini_api\n",
      "    q2_dataset_response = api_handler.generate_from_pil_image(pil_image, q2_dataset_specific)\n",
      "  File \"/Users/jinjiewu/myDermaSynth/DermaSynth/src/gemini_api.py\", line 94, in generate_from_pil_image\n",
      "    response = self.client.models.generate_content(\n",
      "  File \"/Users/jinjiewu/anaconda3/lib/python3.11/site-packages/google/genai/models.py\", line 4945, in generate_content\n",
      "    logger.info(f'AFC remote call {i} is done.')\n",
      "Message: 'AFC remote call 1 is done.'\n",
      "Arguments: ()\n",
      "--- Logging error ---\n",
      "Traceback (most recent call last):\n",
      "  File \"/var/folders/vw/qhm4x34n2tzdd67qh3859yp80000gn/T/ipykernel_3458/2757584945.py\", line 21, in <module>\n",
      "    with open(generated_response_file, \"w\") as out_file:\n",
      "         ^^^^^^^^^^^^^^^^^^^^^^^^^^^^^^^^^^\n",
      "  File \"/Users/jinjiewu/anaconda3/lib/python3.11/site-packages/IPython/core/interactiveshell.py\", line 286, in _modified_open\n",
      "    return io_open(file, *args, **kwargs)\n",
      "           ^^^^^^^^^^^^^^^^^^^^^^^^^^^^^^\n",
      "OSError: [Errno 28] No space left on device: '../api_results/derm12345/DERM_100769.jpg_response.json'\n",
      "\n",
      "During handling of the above exception, another exception occurred:\n",
      "\n",
      "Traceback (most recent call last):\n",
      "  File \"/Users/jinjiewu/anaconda3/lib/python3.11/logging/__init__.py\", line 1114, in emit\n",
      "    self.flush()\n",
      "  File \"/Users/jinjiewu/anaconda3/lib/python3.11/logging/__init__.py\", line 1094, in flush\n",
      "    self.stream.flush()\n",
      "OSError: [Errno 28] No space left on device\n",
      "Call stack:\n",
      "  File \"<frozen runpy>\", line 198, in _run_module_as_main\n",
      "  File \"<frozen runpy>\", line 88, in _run_code\n",
      "  File \"/Users/jinjiewu/anaconda3/lib/python3.11/site-packages/ipykernel_launcher.py\", line 17, in <module>\n",
      "    app.launch_new_instance()\n",
      "  File \"/Users/jinjiewu/anaconda3/lib/python3.11/site-packages/traitlets/config/application.py\", line 992, in launch_instance\n",
      "    app.start()\n",
      "  File \"/Users/jinjiewu/anaconda3/lib/python3.11/site-packages/ipykernel/kernelapp.py\", line 736, in start\n",
      "    self.io_loop.start()\n",
      "  File \"/Users/jinjiewu/anaconda3/lib/python3.11/site-packages/tornado/platform/asyncio.py\", line 195, in start\n",
      "    self.asyncio_loop.run_forever()\n",
      "  File \"/Users/jinjiewu/anaconda3/lib/python3.11/asyncio/base_events.py\", line 607, in run_forever\n",
      "    self._run_once()\n",
      "  File \"/Users/jinjiewu/anaconda3/lib/python3.11/asyncio/base_events.py\", line 1922, in _run_once\n",
      "    handle._run()\n",
      "  File \"/Users/jinjiewu/anaconda3/lib/python3.11/asyncio/events.py\", line 80, in _run\n",
      "    self._context.run(self._callback, *self._args)\n",
      "  File \"/Users/jinjiewu/anaconda3/lib/python3.11/site-packages/ipykernel/kernelbase.py\", line 516, in dispatch_queue\n",
      "    await self.process_one()\n",
      "  File \"/Users/jinjiewu/anaconda3/lib/python3.11/site-packages/ipykernel/kernelbase.py\", line 505, in process_one\n",
      "    await dispatch(*args)\n",
      "  File \"/Users/jinjiewu/anaconda3/lib/python3.11/site-packages/ipykernel/kernelbase.py\", line 412, in dispatch_shell\n",
      "    await result\n",
      "  File \"/Users/jinjiewu/anaconda3/lib/python3.11/site-packages/ipykernel/kernelbase.py\", line 740, in execute_request\n",
      "    reply_content = await reply_content\n",
      "  File \"/Users/jinjiewu/anaconda3/lib/python3.11/site-packages/ipykernel/ipkernel.py\", line 422, in do_execute\n",
      "    res = shell.run_cell(\n",
      "  File \"/Users/jinjiewu/anaconda3/lib/python3.11/site-packages/ipykernel/zmqshell.py\", line 546, in run_cell\n",
      "    return super().run_cell(*args, **kwargs)\n",
      "  File \"/Users/jinjiewu/anaconda3/lib/python3.11/site-packages/IPython/core/interactiveshell.py\", line 3024, in run_cell\n",
      "    result = self._run_cell(\n",
      "  File \"/Users/jinjiewu/anaconda3/lib/python3.11/site-packages/IPython/core/interactiveshell.py\", line 3079, in _run_cell\n",
      "    result = runner(coro)\n",
      "  File \"/Users/jinjiewu/anaconda3/lib/python3.11/site-packages/IPython/core/async_helpers.py\", line 129, in _pseudo_sync_runner\n",
      "    coro.send(None)\n",
      "  File \"/Users/jinjiewu/anaconda3/lib/python3.11/site-packages/IPython/core/interactiveshell.py\", line 3284, in run_cell_async\n",
      "    has_raised = await self.run_ast_nodes(code_ast.body, cell_name,\n",
      "  File \"/Users/jinjiewu/anaconda3/lib/python3.11/site-packages/IPython/core/interactiveshell.py\", line 3466, in run_ast_nodes\n",
      "    if await self.run_code(code, result, async_=asy):\n",
      "  File \"/Users/jinjiewu/anaconda3/lib/python3.11/site-packages/IPython/core/interactiveshell.py\", line 3526, in run_code\n",
      "    exec(code_obj, self.user_global_ns, self.user_ns)\n",
      "  File \"/var/folders/vw/qhm4x34n2tzdd67qh3859yp80000gn/T/ipykernel_3458/2757584945.py\", line 26, in <module>\n",
      "    logger.warning(f\"Error processing image_id {image_id}: {e}\")\n",
      "Message: \"Error processing image_id DERM_100769.jpg: [Errno 28] No space left on device: '../api_results/derm12345/DERM_100769.jpg_response.json'\"\n",
      "Arguments: ()\n",
      "--- Logging error ---\n",
      "Traceback (most recent call last):\n",
      "  File \"/Users/jinjiewu/anaconda3/lib/python3.11/logging/__init__.py\", line 1114, in emit\n",
      "    self.flush()\n",
      "  File \"/Users/jinjiewu/anaconda3/lib/python3.11/logging/__init__.py\", line 1094, in flush\n",
      "    self.stream.flush()\n",
      "OSError: [Errno 28] No space left on device\n",
      "Call stack:\n",
      "  File \"<frozen runpy>\", line 198, in _run_module_as_main\n",
      "  File \"<frozen runpy>\", line 88, in _run_code\n",
      "  File \"/Users/jinjiewu/anaconda3/lib/python3.11/site-packages/ipykernel_launcher.py\", line 17, in <module>\n",
      "    app.launch_new_instance()\n",
      "  File \"/Users/jinjiewu/anaconda3/lib/python3.11/site-packages/traitlets/config/application.py\", line 992, in launch_instance\n",
      "    app.start()\n",
      "  File \"/Users/jinjiewu/anaconda3/lib/python3.11/site-packages/ipykernel/kernelapp.py\", line 736, in start\n",
      "    self.io_loop.start()\n",
      "  File \"/Users/jinjiewu/anaconda3/lib/python3.11/site-packages/tornado/platform/asyncio.py\", line 195, in start\n",
      "    self.asyncio_loop.run_forever()\n",
      "  File \"/Users/jinjiewu/anaconda3/lib/python3.11/asyncio/base_events.py\", line 607, in run_forever\n",
      "    self._run_once()\n",
      "  File \"/Users/jinjiewu/anaconda3/lib/python3.11/asyncio/base_events.py\", line 1922, in _run_once\n",
      "    handle._run()\n",
      "  File \"/Users/jinjiewu/anaconda3/lib/python3.11/asyncio/events.py\", line 80, in _run\n",
      "    self._context.run(self._callback, *self._args)\n",
      "  File \"/Users/jinjiewu/anaconda3/lib/python3.11/site-packages/ipykernel/kernelbase.py\", line 516, in dispatch_queue\n",
      "    await self.process_one()\n",
      "  File \"/Users/jinjiewu/anaconda3/lib/python3.11/site-packages/ipykernel/kernelbase.py\", line 505, in process_one\n",
      "    await dispatch(*args)\n",
      "  File \"/Users/jinjiewu/anaconda3/lib/python3.11/site-packages/ipykernel/kernelbase.py\", line 412, in dispatch_shell\n",
      "    await result\n",
      "  File \"/Users/jinjiewu/anaconda3/lib/python3.11/site-packages/ipykernel/kernelbase.py\", line 740, in execute_request\n",
      "    reply_content = await reply_content\n",
      "  File \"/Users/jinjiewu/anaconda3/lib/python3.11/site-packages/ipykernel/ipkernel.py\", line 422, in do_execute\n",
      "    res = shell.run_cell(\n",
      "  File \"/Users/jinjiewu/anaconda3/lib/python3.11/site-packages/ipykernel/zmqshell.py\", line 546, in run_cell\n",
      "    return super().run_cell(*args, **kwargs)\n",
      "  File \"/Users/jinjiewu/anaconda3/lib/python3.11/site-packages/IPython/core/interactiveshell.py\", line 3024, in run_cell\n",
      "    result = self._run_cell(\n",
      "  File \"/Users/jinjiewu/anaconda3/lib/python3.11/site-packages/IPython/core/interactiveshell.py\", line 3079, in _run_cell\n",
      "    result = runner(coro)\n",
      "  File \"/Users/jinjiewu/anaconda3/lib/python3.11/site-packages/IPython/core/async_helpers.py\", line 129, in _pseudo_sync_runner\n",
      "    coro.send(None)\n",
      "  File \"/Users/jinjiewu/anaconda3/lib/python3.11/site-packages/IPython/core/interactiveshell.py\", line 3284, in run_cell_async\n",
      "    has_raised = await self.run_ast_nodes(code_ast.body, cell_name,\n",
      "  File \"/Users/jinjiewu/anaconda3/lib/python3.11/site-packages/IPython/core/interactiveshell.py\", line 3466, in run_ast_nodes\n",
      "    if await self.run_code(code, result, async_=asy):\n",
      "  File \"/Users/jinjiewu/anaconda3/lib/python3.11/site-packages/IPython/core/interactiveshell.py\", line 3526, in run_code\n",
      "    exec(code_obj, self.user_global_ns, self.user_ns)\n",
      "  File \"/var/folders/vw/qhm4x34n2tzdd67qh3859yp80000gn/T/ipykernel_3458/2757584945.py\", line 19, in <module>\n",
      "    result = call_gemini_api(request)\n",
      "  File \"/var/folders/vw/qhm4x34n2tzdd67qh3859yp80000gn/T/ipykernel_3458/388332256.py\", line 15, in call_gemini_api\n",
      "    q1_general_response = api_handler.generate_from_pil_image(pil_image, q1_general)\n",
      "  File \"/Users/jinjiewu/myDermaSynth/DermaSynth/src/gemini_api.py\", line 94, in generate_from_pil_image\n",
      "    response = self.client.models.generate_content(\n",
      "  File \"/Users/jinjiewu/anaconda3/lib/python3.11/site-packages/google/genai/models.py\", line 4934, in generate_content\n",
      "    logger.info(\n",
      "Message: 'AFC is enabled with max remote calls: 10.'\n",
      "Arguments: ()\n",
      "--- Logging error ---\n",
      "Traceback (most recent call last):\n",
      "  File \"/Users/jinjiewu/anaconda3/lib/python3.11/logging/__init__.py\", line 1114, in emit\n",
      "    self.flush()\n",
      "  File \"/Users/jinjiewu/anaconda3/lib/python3.11/logging/__init__.py\", line 1094, in flush\n",
      "    self.stream.flush()\n",
      "OSError: [Errno 28] No space left on device\n",
      "Call stack:\n",
      "  File \"<frozen runpy>\", line 198, in _run_module_as_main\n",
      "  File \"<frozen runpy>\", line 88, in _run_code\n",
      "  File \"/Users/jinjiewu/anaconda3/lib/python3.11/site-packages/ipykernel_launcher.py\", line 17, in <module>\n",
      "    app.launch_new_instance()\n",
      "  File \"/Users/jinjiewu/anaconda3/lib/python3.11/site-packages/traitlets/config/application.py\", line 992, in launch_instance\n",
      "    app.start()\n",
      "  File \"/Users/jinjiewu/anaconda3/lib/python3.11/site-packages/ipykernel/kernelapp.py\", line 736, in start\n",
      "    self.io_loop.start()\n",
      "  File \"/Users/jinjiewu/anaconda3/lib/python3.11/site-packages/tornado/platform/asyncio.py\", line 195, in start\n",
      "    self.asyncio_loop.run_forever()\n",
      "  File \"/Users/jinjiewu/anaconda3/lib/python3.11/asyncio/base_events.py\", line 607, in run_forever\n",
      "    self._run_once()\n",
      "  File \"/Users/jinjiewu/anaconda3/lib/python3.11/asyncio/base_events.py\", line 1922, in _run_once\n",
      "    handle._run()\n",
      "  File \"/Users/jinjiewu/anaconda3/lib/python3.11/asyncio/events.py\", line 80, in _run\n",
      "    self._context.run(self._callback, *self._args)\n",
      "  File \"/Users/jinjiewu/anaconda3/lib/python3.11/site-packages/ipykernel/kernelbase.py\", line 516, in dispatch_queue\n",
      "    await self.process_one()\n",
      "  File \"/Users/jinjiewu/anaconda3/lib/python3.11/site-packages/ipykernel/kernelbase.py\", line 505, in process_one\n",
      "    await dispatch(*args)\n",
      "  File \"/Users/jinjiewu/anaconda3/lib/python3.11/site-packages/ipykernel/kernelbase.py\", line 412, in dispatch_shell\n",
      "    await result\n",
      "  File \"/Users/jinjiewu/anaconda3/lib/python3.11/site-packages/ipykernel/kernelbase.py\", line 740, in execute_request\n",
      "    reply_content = await reply_content\n",
      "  File \"/Users/jinjiewu/anaconda3/lib/python3.11/site-packages/ipykernel/ipkernel.py\", line 422, in do_execute\n",
      "    res = shell.run_cell(\n",
      "  File \"/Users/jinjiewu/anaconda3/lib/python3.11/site-packages/ipykernel/zmqshell.py\", line 546, in run_cell\n",
      "    return super().run_cell(*args, **kwargs)\n",
      "  File \"/Users/jinjiewu/anaconda3/lib/python3.11/site-packages/IPython/core/interactiveshell.py\", line 3024, in run_cell\n",
      "    result = self._run_cell(\n",
      "  File \"/Users/jinjiewu/anaconda3/lib/python3.11/site-packages/IPython/core/interactiveshell.py\", line 3079, in _run_cell\n",
      "    result = runner(coro)\n",
      "  File \"/Users/jinjiewu/anaconda3/lib/python3.11/site-packages/IPython/core/async_helpers.py\", line 129, in _pseudo_sync_runner\n",
      "    coro.send(None)\n",
      "  File \"/Users/jinjiewu/anaconda3/lib/python3.11/site-packages/IPython/core/interactiveshell.py\", line 3284, in run_cell_async\n",
      "    has_raised = await self.run_ast_nodes(code_ast.body, cell_name,\n",
      "  File \"/Users/jinjiewu/anaconda3/lib/python3.11/site-packages/IPython/core/interactiveshell.py\", line 3466, in run_ast_nodes\n",
      "    if await self.run_code(code, result, async_=asy):\n",
      "  File \"/Users/jinjiewu/anaconda3/lib/python3.11/site-packages/IPython/core/interactiveshell.py\", line 3526, in run_code\n",
      "    exec(code_obj, self.user_global_ns, self.user_ns)\n",
      "  File \"/var/folders/vw/qhm4x34n2tzdd67qh3859yp80000gn/T/ipykernel_3458/2757584945.py\", line 19, in <module>\n",
      "    result = call_gemini_api(request)\n",
      "  File \"/var/folders/vw/qhm4x34n2tzdd67qh3859yp80000gn/T/ipykernel_3458/388332256.py\", line 15, in call_gemini_api\n",
      "    q1_general_response = api_handler.generate_from_pil_image(pil_image, q1_general)\n",
      "  File \"/Users/jinjiewu/myDermaSynth/DermaSynth/src/gemini_api.py\", line 94, in generate_from_pil_image\n",
      "    response = self.client.models.generate_content(\n",
      "  File \"/Users/jinjiewu/anaconda3/lib/python3.11/site-packages/google/genai/models.py\", line 4942, in generate_content\n",
      "    response = self._generate_content(\n",
      "  File \"/Users/jinjiewu/anaconda3/lib/python3.11/site-packages/google/genai/models.py\", line 3915, in _generate_content\n",
      "    response_dict = self._api_client.request(\n",
      "  File \"/Users/jinjiewu/anaconda3/lib/python3.11/site-packages/google/genai/_api_client.py\", line 655, in request\n",
      "    response = self._request(http_request, stream=False)\n",
      "  File \"/Users/jinjiewu/anaconda3/lib/python3.11/site-packages/google/genai/_api_client.py\", line 577, in _request\n",
      "    response = self._httpx_client.request(\n",
      "  File \"/Users/jinjiewu/anaconda3/lib/python3.11/site-packages/httpx/_client.py\", line 825, in request\n",
      "    return self.send(request, auth=auth, follow_redirects=follow_redirects)\n",
      "  File \"/Users/jinjiewu/anaconda3/lib/python3.11/site-packages/httpx/_client.py\", line 914, in send\n",
      "    response = self._send_handling_auth(\n",
      "  File \"/Users/jinjiewu/anaconda3/lib/python3.11/site-packages/httpx/_client.py\", line 942, in _send_handling_auth\n",
      "    response = self._send_handling_redirects(\n",
      "  File \"/Users/jinjiewu/anaconda3/lib/python3.11/site-packages/httpx/_client.py\", line 979, in _send_handling_redirects\n",
      "    response = self._send_single_request(request)\n",
      "  File \"/Users/jinjiewu/anaconda3/lib/python3.11/site-packages/httpx/_client.py\", line 1025, in _send_single_request\n",
      "    logger.info(\n",
      "Message: 'HTTP Request: %s %s \"%s %d %s\"'\n",
      "Arguments: ('POST', URL('https://generativelanguage.googleapis.com/v1beta/models/gemini-2.0-flash-exp:generateContent'), 'HTTP/1.1', 200, 'OK')\n",
      "--- Logging error ---\n",
      "Traceback (most recent call last):\n",
      "  File \"/Users/jinjiewu/anaconda3/lib/python3.11/logging/__init__.py\", line 1114, in emit\n",
      "    self.flush()\n",
      "  File \"/Users/jinjiewu/anaconda3/lib/python3.11/logging/__init__.py\", line 1094, in flush\n",
      "    self.stream.flush()\n",
      "OSError: [Errno 28] No space left on device\n",
      "Call stack:\n",
      "  File \"<frozen runpy>\", line 198, in _run_module_as_main\n",
      "  File \"<frozen runpy>\", line 88, in _run_code\n",
      "  File \"/Users/jinjiewu/anaconda3/lib/python3.11/site-packages/ipykernel_launcher.py\", line 17, in <module>\n",
      "    app.launch_new_instance()\n",
      "  File \"/Users/jinjiewu/anaconda3/lib/python3.11/site-packages/traitlets/config/application.py\", line 992, in launch_instance\n",
      "    app.start()\n",
      "  File \"/Users/jinjiewu/anaconda3/lib/python3.11/site-packages/ipykernel/kernelapp.py\", line 736, in start\n",
      "    self.io_loop.start()\n",
      "  File \"/Users/jinjiewu/anaconda3/lib/python3.11/site-packages/tornado/platform/asyncio.py\", line 195, in start\n",
      "    self.asyncio_loop.run_forever()\n",
      "  File \"/Users/jinjiewu/anaconda3/lib/python3.11/asyncio/base_events.py\", line 607, in run_forever\n",
      "    self._run_once()\n",
      "  File \"/Users/jinjiewu/anaconda3/lib/python3.11/asyncio/base_events.py\", line 1922, in _run_once\n",
      "    handle._run()\n",
      "  File \"/Users/jinjiewu/anaconda3/lib/python3.11/asyncio/events.py\", line 80, in _run\n",
      "    self._context.run(self._callback, *self._args)\n",
      "  File \"/Users/jinjiewu/anaconda3/lib/python3.11/site-packages/ipykernel/kernelbase.py\", line 516, in dispatch_queue\n",
      "    await self.process_one()\n",
      "  File \"/Users/jinjiewu/anaconda3/lib/python3.11/site-packages/ipykernel/kernelbase.py\", line 505, in process_one\n",
      "    await dispatch(*args)\n",
      "  File \"/Users/jinjiewu/anaconda3/lib/python3.11/site-packages/ipykernel/kernelbase.py\", line 412, in dispatch_shell\n",
      "    await result\n",
      "  File \"/Users/jinjiewu/anaconda3/lib/python3.11/site-packages/ipykernel/kernelbase.py\", line 740, in execute_request\n",
      "    reply_content = await reply_content\n",
      "  File \"/Users/jinjiewu/anaconda3/lib/python3.11/site-packages/ipykernel/ipkernel.py\", line 422, in do_execute\n",
      "    res = shell.run_cell(\n",
      "  File \"/Users/jinjiewu/anaconda3/lib/python3.11/site-packages/ipykernel/zmqshell.py\", line 546, in run_cell\n",
      "    return super().run_cell(*args, **kwargs)\n",
      "  File \"/Users/jinjiewu/anaconda3/lib/python3.11/site-packages/IPython/core/interactiveshell.py\", line 3024, in run_cell\n",
      "    result = self._run_cell(\n",
      "  File \"/Users/jinjiewu/anaconda3/lib/python3.11/site-packages/IPython/core/interactiveshell.py\", line 3079, in _run_cell\n",
      "    result = runner(coro)\n",
      "  File \"/Users/jinjiewu/anaconda3/lib/python3.11/site-packages/IPython/core/async_helpers.py\", line 129, in _pseudo_sync_runner\n",
      "    coro.send(None)\n",
      "  File \"/Users/jinjiewu/anaconda3/lib/python3.11/site-packages/IPython/core/interactiveshell.py\", line 3284, in run_cell_async\n",
      "    has_raised = await self.run_ast_nodes(code_ast.body, cell_name,\n",
      "  File \"/Users/jinjiewu/anaconda3/lib/python3.11/site-packages/IPython/core/interactiveshell.py\", line 3466, in run_ast_nodes\n",
      "    if await self.run_code(code, result, async_=asy):\n",
      "  File \"/Users/jinjiewu/anaconda3/lib/python3.11/site-packages/IPython/core/interactiveshell.py\", line 3526, in run_code\n",
      "    exec(code_obj, self.user_global_ns, self.user_ns)\n",
      "  File \"/var/folders/vw/qhm4x34n2tzdd67qh3859yp80000gn/T/ipykernel_3458/2757584945.py\", line 19, in <module>\n",
      "    result = call_gemini_api(request)\n",
      "  File \"/var/folders/vw/qhm4x34n2tzdd67qh3859yp80000gn/T/ipykernel_3458/388332256.py\", line 15, in call_gemini_api\n",
      "    q1_general_response = api_handler.generate_from_pil_image(pil_image, q1_general)\n",
      "  File \"/Users/jinjiewu/myDermaSynth/DermaSynth/src/gemini_api.py\", line 94, in generate_from_pil_image\n",
      "    response = self.client.models.generate_content(\n",
      "  File \"/Users/jinjiewu/anaconda3/lib/python3.11/site-packages/google/genai/models.py\", line 4945, in generate_content\n",
      "    logger.info(f'AFC remote call {i} is done.')\n",
      "Message: 'AFC remote call 1 is done.'\n",
      "Arguments: ()\n",
      "--- Logging error ---\n",
      "Traceback (most recent call last):\n",
      "  File \"/Users/jinjiewu/anaconda3/lib/python3.11/logging/__init__.py\", line 1114, in emit\n",
      "    self.flush()\n",
      "  File \"/Users/jinjiewu/anaconda3/lib/python3.11/logging/__init__.py\", line 1094, in flush\n",
      "    self.stream.flush()\n",
      "OSError: [Errno 28] No space left on device\n",
      "Call stack:\n",
      "  File \"<frozen runpy>\", line 198, in _run_module_as_main\n",
      "  File \"<frozen runpy>\", line 88, in _run_code\n",
      "  File \"/Users/jinjiewu/anaconda3/lib/python3.11/site-packages/ipykernel_launcher.py\", line 17, in <module>\n",
      "    app.launch_new_instance()\n",
      "  File \"/Users/jinjiewu/anaconda3/lib/python3.11/site-packages/traitlets/config/application.py\", line 992, in launch_instance\n",
      "    app.start()\n",
      "  File \"/Users/jinjiewu/anaconda3/lib/python3.11/site-packages/ipykernel/kernelapp.py\", line 736, in start\n",
      "    self.io_loop.start()\n",
      "  File \"/Users/jinjiewu/anaconda3/lib/python3.11/site-packages/tornado/platform/asyncio.py\", line 195, in start\n",
      "    self.asyncio_loop.run_forever()\n",
      "  File \"/Users/jinjiewu/anaconda3/lib/python3.11/asyncio/base_events.py\", line 607, in run_forever\n",
      "    self._run_once()\n",
      "  File \"/Users/jinjiewu/anaconda3/lib/python3.11/asyncio/base_events.py\", line 1922, in _run_once\n",
      "    handle._run()\n",
      "  File \"/Users/jinjiewu/anaconda3/lib/python3.11/asyncio/events.py\", line 80, in _run\n",
      "    self._context.run(self._callback, *self._args)\n",
      "  File \"/Users/jinjiewu/anaconda3/lib/python3.11/site-packages/ipykernel/kernelbase.py\", line 516, in dispatch_queue\n",
      "    await self.process_one()\n",
      "  File \"/Users/jinjiewu/anaconda3/lib/python3.11/site-packages/ipykernel/kernelbase.py\", line 505, in process_one\n",
      "    await dispatch(*args)\n",
      "  File \"/Users/jinjiewu/anaconda3/lib/python3.11/site-packages/ipykernel/kernelbase.py\", line 412, in dispatch_shell\n",
      "    await result\n",
      "  File \"/Users/jinjiewu/anaconda3/lib/python3.11/site-packages/ipykernel/kernelbase.py\", line 740, in execute_request\n",
      "    reply_content = await reply_content\n",
      "  File \"/Users/jinjiewu/anaconda3/lib/python3.11/site-packages/ipykernel/ipkernel.py\", line 422, in do_execute\n",
      "    res = shell.run_cell(\n",
      "  File \"/Users/jinjiewu/anaconda3/lib/python3.11/site-packages/ipykernel/zmqshell.py\", line 546, in run_cell\n",
      "    return super().run_cell(*args, **kwargs)\n",
      "  File \"/Users/jinjiewu/anaconda3/lib/python3.11/site-packages/IPython/core/interactiveshell.py\", line 3024, in run_cell\n",
      "    result = self._run_cell(\n",
      "  File \"/Users/jinjiewu/anaconda3/lib/python3.11/site-packages/IPython/core/interactiveshell.py\", line 3079, in _run_cell\n",
      "    result = runner(coro)\n",
      "  File \"/Users/jinjiewu/anaconda3/lib/python3.11/site-packages/IPython/core/async_helpers.py\", line 129, in _pseudo_sync_runner\n",
      "    coro.send(None)\n",
      "  File \"/Users/jinjiewu/anaconda3/lib/python3.11/site-packages/IPython/core/interactiveshell.py\", line 3284, in run_cell_async\n",
      "    has_raised = await self.run_ast_nodes(code_ast.body, cell_name,\n",
      "  File \"/Users/jinjiewu/anaconda3/lib/python3.11/site-packages/IPython/core/interactiveshell.py\", line 3466, in run_ast_nodes\n",
      "    if await self.run_code(code, result, async_=asy):\n",
      "  File \"/Users/jinjiewu/anaconda3/lib/python3.11/site-packages/IPython/core/interactiveshell.py\", line 3526, in run_code\n",
      "    exec(code_obj, self.user_global_ns, self.user_ns)\n",
      "  File \"/var/folders/vw/qhm4x34n2tzdd67qh3859yp80000gn/T/ipykernel_3458/2757584945.py\", line 19, in <module>\n",
      "    result = call_gemini_api(request)\n",
      "  File \"/var/folders/vw/qhm4x34n2tzdd67qh3859yp80000gn/T/ipykernel_3458/388332256.py\", line 17, in call_gemini_api\n",
      "    q2_dataset_response = api_handler.generate_from_pil_image(pil_image, q2_dataset_specific)\n",
      "  File \"/Users/jinjiewu/myDermaSynth/DermaSynth/src/gemini_api.py\", line 94, in generate_from_pil_image\n",
      "    response = self.client.models.generate_content(\n",
      "  File \"/Users/jinjiewu/anaconda3/lib/python3.11/site-packages/google/genai/models.py\", line 4934, in generate_content\n",
      "    logger.info(\n",
      "Message: 'AFC is enabled with max remote calls: 10.'\n",
      "Arguments: ()\n"
     ]
    }
   ],
   "source": [
    "requests_queue = Queue()\n",
    "for req in api_requests:\n",
    "    requests_queue.put(req)\n",
    "\n",
    "results = []\n",
    "\n",
    "while not requests_queue.empty():\n",
    "    request = requests_queue.get()\n",
    "    task_exists = False\n",
    "    try:\n",
    "        image_id = request.get(\"image_id\")\n",
    "        generated_response_file = os.path.join(output_dir, f\"{image_id}_response.json\")\n",
    "        \n",
    "        if os.path.exists(generated_response_file):\n",
    "            logger.info(f\"Skipping image_id {image_id} as response already exists.\")\n",
    "            task_exists = True\n",
    "\n",
    "        else:\n",
    "            result = call_gemini_api(request)\n",
    "            results.append(result)\n",
    "            with open(generated_response_file, \"w\") as out_file:\n",
    "                json.dump(result, out_file, indent=4)\n",
    "            logger.info(f\"Successfully processed image_id {image_id}, saved to {generated_response_file}\")\n",
    "\n",
    "    except Exception as e:\n",
    "        logger.warning(f\"Error processing image_id {image_id}: {e}\")\n",
    "        \n",
    "        # Requeue the request\n",
    "        requests_queue.put(request)\n",
    "\n",
    "    finally:\n",
    "        requests_queue.task_done()\n"
   ]
  }
 ],
 "metadata": {
  "kernelspec": {
   "display_name": "base",
   "language": "python",
   "name": "python3"
  },
  "language_info": {
   "codemirror_mode": {
    "name": "ipython",
    "version": 3
   },
   "file_extension": ".py",
   "mimetype": "text/x-python",
   "name": "python",
   "nbconvert_exporter": "python",
   "pygments_lexer": "ipython3",
   "version": "3.11.5"
  }
 },
 "nbformat": 4,
 "nbformat_minor": 2
}
